Workbook
Name JULIANROA: CLIENTES!$A$30
Name ROAJULIAN: CLIENTES!$A$30
Name VERA_LUIS__ELECTROVERA: "JULIANROA"

Sheet CLIENTES
B1: MONTO PENDIENTE | C1: CELULAR
A2: AGUILAR FELIPE (BULLA) | B2: =VALUE('AGUILAR FELIPE (BULLA)'!J2) -> 538000
A3: AGUILAR FELIPE (BULLA) LICAN | B3: $
A4: BAHAMONDEZ JORGE | B4: =VALUE('BAHAMONDEZ JORGE'!J2) -> 0
A5: BARRIA MIGUEL | B5: =VALUE('BARRIA MIGUEL'!J2) -> 3000
A6: CANALES JOSE LUIS (MACACO) | B6: =VALUE('CANALES JOSE LUIS'!J2) -> 0
A7: CARDENAS GABRIEL | B7: =VALUE('CARDENAS GABRIEL'!J2) -> 58000 | C7: 15000
A8: CEA RAUL | B8: =VALUE('CEA RAUL'!J2) -> 164000
A9: COMIGUAL HUGO | B9: =VALUE('COMIGUAL HUGO'!J2) -> 87500
A10: DEL RIO LORCA EMERSON | B10: =VALUE('DEL RIO LORCA EMERSON'!J2) -> 130000
A11: DELGADO PATRICIO (RAPIDO Y FUR) | B11: =VALUE('DELGADO PATRICIO (RAPIDO Y FUR)'!J2) -> 0
A12: FOLLERT CARDENAS JOSE | B12: =VALUE('FOLLERT CARDENAS JOSE'!J2) -> 0
A13: FUENTES HECTOR | B13: =VALUE('FUENTES HECTOR'!J2) -> 0
A14: GALLARDO ARMANDO | B14: =VALUE('GALLARDO ARMANDO'!J2) -> 0
A15: GONZALEZ NELSON | B15: =VALUE('GONZALEZ NELSON'!J2) -> 25000
A16: GUERRERO RODRIGO | B16: =VALUE('GUERRERO RODRIGO'!J2) -> 0
A17: HANZ AGUILAR | B17: =VALUE('AGUILAR HANZ'!J2) -> 189000
A18: HECTOR HERNNADEZ (FALABELLA) | B18: =VALUE('HERNANDEZ HECTOR (FALABELLA)'!J2) -> 0
A19: HENRIQUES JORGE (HUEVO) | B19: =VALUE('HENRIQUES JORGE (HUEVO)'!J2) -> 12000
A20: HINOSTROZA MOISES (LA CUMBRE) | B20: =VALUE('HINOSTROZA MOISES (LA CUMBRE)'!J2) -> 0 | C20: 478500
A21: LORCA EMERSON | B21: 0
A22: MALDONADO MOISES
A23: MANUEL ROA | B23: =VALUE('ROA MANUEL'!J2) -> 356000
A24: MARCO BAHAMONDEZ (SUBOFICIAL) | B24: =VALUE('BAHAMONDEZ MARCO (SUBOFICIAL)'!J2) -> 201500
A25: MARTINEZ EDUARDO (FUSCHLOCHER) | B25: =VALUE('MARTINEZ EDUARDO (FUSCHLOCHER)'!J2) -> 0
A26: MAURICIO VALENZUELA(MALO PAL SEXO) | B26: 187500 | C26: saldo y repuestos yaris repuestos platina | E26: abono 08/04/2022 | F26: bateria 70 amperes stp $70000 12/08/2022 | G26: TOTAL$197500 ABONO $60000 9/07/2023
A27: MENARES MAIKOL (GRUA) | B27: =VALUE('MENARES MAIKOL (GRUA)'!J2) -> 110000
A28: MONTES WALTER (LOCO EDY) | B28: =VALUE('MONTES WALTER (LOCO EDY)'!J2) -> 159000
A29: MOTOR EXPRESS | B29: =VALUE('MOTOR EXPRESS'!J2) -> 898400
A30: PEDRO CARRASCO (ZORRO) | B30: =VALUE('CARRASCO PEDRO (ZORRO)'!J2) -> 28000
A31: PEREZ SADY
A32: PINGÜINO MAURI | B32: =VALUE('PINGUINO MAURI'!J2) -> 0
A33: PINUER OMAR | B33: =VALUE('PINUER OMAR'!J2) -> 126000
A34: PORTALES CRISTIAN | B34: =VALUE('PORTALES CRISTIAN'!J2) -> 1244000
A35: PUSCHEL PABLO | B35: =VALUE('PUSCHEL PABLO'!J2) -> 0 | C35: ALSACIA | E35: 580000
A36: QUEZADA RICHARD | B36: =VALUE('QUEZADA RICHARD'!J2) -> 0
A37: REYES ANDRES (PIRLO) | B37: =VALUE('REYES ANDRES (PIRLO)'!J2) -> 0
A38: RICARDO 5L | B38: =VALUE('RICARDO 5L'!J2) -> 0
A39: ROA JULIAN | B39: =VALUE('ROA JULIAN'!J2) -> 0
A40: ROBLES LUIS | B40: 0
...

Sheet PLANTILLA
A1: FECHA | B1: REPUESTO | C1: PRECIO | D1: CONDICION | E1: FACTURA | F1: VENDEDOR | H1: FACTURA | I1: DEUDA | J1: TOTAL DEUDA
C2: 0 | H2: =IF(E:E="NO FACTURADO","PENDIENTE","AL DIA") -> AL DIA | I2: =IF(D2="PENDIENTE",C2,0) -> 0 | J2: =SUM(I:I) -> 0 | K2: MENU
I3: =IF(D3="PENDIENTE",C3,0) -> 0
I4: =IF(D4="PENDIENTE",C4,0) -> 0
I5: =IF(D5="PENDIENTE",C5,0) -> 0
I6: =IF(D6="PENDIENTE",C6,0) -> 0
I7: =IF(D7="PENDIENTE",C7,0) -> 0
I8: =IF(D8="PENDIENTE",C8,0) -> 0
I9: =IF(D9="PENDIENTE",C9,0) -> 0
I10: =IF(D10="PENDIENTE",C10,0) -> 0
I11: =IF(D11="PENDIENTE",C11,0) -> 0
I12: =IF(D12="PENDIENTE",C12,0) -> 0
I13: =IF(D13="PENDIENTE",C13,0) -> 0
I14: =IF(D14="PENDIENTE",C14,0) -> 0
... I37: =IF(D37="PENDIENTE",C37,0) -> 0

Sheet PEDRO NEGRONI 
A1: FECHA | B1: REPUESTO | C1: PRECIO | D1: CONDICION | E1: FACTURA | F1: VENDEDOR | H1: FACTURA | I1: DEUDA | J1: TOTAL DEUDA
C2: 0 | H2: =IF(E:E="NO FACTURADO","PENDIENTE","AL DIA") -> AL DIA | I2: =IF(D2="PENDIENTE",C2,0) -> 0 | J2: =SUM(I:I) -> 8000 | K2: MENU
A3: 45618 | B3: aceite y filtro | C3: 8000 | D3: pendiente | E3: saldo aceite | I3: =IF(D3="PENDIENTE",C3,0) -> 8000
I4: =IF(D4="PENDIENTE",C4,0) -> 0
I5: =IF(D5="PENDIENTE",C5,0) -> 0
I6: =IF(D6="PENDIENTE",C6,0) -> 0
I7: =IF(D7="PENDIENTE",C7,0) -> 0
I8: =IF(D8="PENDIENTE",C8,0) -> 0
I9: =IF(D9="PENDIENTE",C9,0) -> 0
I10: =IF(D10="PENDIENTE",C10,0) -> 0
I11: =IF(D11="PENDIENTE",C11,0) -> 0
I12: =IF(D12="PENDIENTE",C12,0) -> 0
I13: =IF(D13="PENDIENTE",C13,0) -> 0
I14: =IF(D14="PENDIENTE",C14,0) -> 0
I15: =IF(D15="PENDIENTE",C15,0) -> 0
... I37: =IF(D37="PENDIENTE",C37,0) -> 0

Sheet JORGE CEA HERMANO RAUL CEA
A1: FECHA | B1: REPUESTO | C1: PRECIO | D1: CONDICION | E1: FACTURA | F1: VENDEDOR | H1: FACTURA | I1: DEUDA | J1: TOTAL DEUDA
C2: 0 | H2: =IF(E:E="NO FACTURADO","PENDIENTE","AL DIA") -> AL DIA | I2: =IF(D2="PENDIENTE",C2,0) -> 0 | J2: =SUM(I:I) -> 0 | K2: MENU
I3: =IF(D3="PENDIENTE",C3,0) -> 0
I4: =IF(D4="PENDIENTE",C4,0) -> 0
I5: =IF(D5="PENDIENTE",C5,0) -> 0
I6: =IF(D6="PENDIENTE",C6,0) -> 0
I7: =IF(D7="PENDIENTE",C7,0) -> 0
I8: =IF(D8="PENDIENTE",C8,0) -> 0
I9: =IF(D9="PENDIENTE",C9,0) -> 0
I10: =IF(D10="PENDIENTE",C10,0) -> 0
I11: =IF(D11="PENDIENTE",C11,0) -> 0
I12: =IF(D12="PENDIENTE",C12,0) -> 0
I13: =IF(D13="PENDIENTE",C13,0) -> 0
I14: =IF(D14="PENDIENTE",C14,0) -> 0
... I37: =IF(D37="PENDIENTE",C37,0) -> 0

Sheet ALEMBERTH MORALES
A1: FECHA | B1: REPUESTO | C1: PRECIO | D1: CONDICION | E1: FACTURA | F1: VENDEDOR | H1: FACTURA | I1: DEUDA | J1: TOTAL DEUDA
C2: 0 | H2: =IF(E:E="NO FACTURADO","PENDIENTE","AL DIA") -> AL DIA | I2: =IF(D2="PENDIENTE",C2,0) -> 0 | J2: =SUM(I:I) -> 0 | K2: MENU
I3: =IF(D3="PENDIENTE",C3,0) -> 0
I4: =IF(D4="PENDIENTE",C4,0) -> 0
I5: =IF(D5="PENDIENTE",C5,0) -> 0
I6: =IF(D6="PENDIENTE",C6,0) -> 0
I7: =IF(D7="PENDIENTE",C7,0) -> 0
I8: =IF(D8="PENDIENTE",C8,0) -> 0
I9: =IF(D9="PENDIENTE",C9,0) -> 0
I10: =IF(D10="PENDIENTE",C10,0) -> 0
I11: =IF(D11="PENDIENTE",C11,0) -> 0
I12: =IF(D12="PENDIENTE",C12,0) -> 0
I13: =IF(D13="PENDIENTE",C13,0) -> 0
I14: =IF(D14="PENDIENTE",C14,0) -> 0
... I37: =IF(D37="PENDIENTE",C37,0) -> 0

Sheet vecino fruteria sra Marta 
A1: FECHA | B1: REPUESTO | C1: PRECIO | D1: CONDICION | E1: FACTURA | F1: VENDEDOR | H1: FACTURA | I1: DEUDA | J1: TOTAL DEUDA
C2: 0 | H2: =IF(E:E="NO FACTURADO","PENDIENTE","AL DIA") -> AL DIA | I2: =IF(D2="PENDIENTE",C2,0) -> 0 | J2: =SUM(I:I) -> 0 | K2: MENU
I3: =IF(D3="PENDIENTE",C3,0) -> 0
I4: =IF(D4="PENDIENTE",C4,0) -> 0
I5: =IF(D5="PENDIENTE",C5,0) -> 0
I6: =IF(D6="PENDIENTE",C6,0) -> 0
I7: =IF(D7="PENDIENTE",C7,0) -> 0
I8: =IF(D8="PENDIENTE",C8,0) -> 0
I9: =IF(D9="PENDIENTE",C9,0) -> 0
I10: =IF(D10="PENDIENTE",C10,0) -> 0
I11: =IF(D11="PENDIENTE",C11,0) -> 0
I12: =IF(D12="PENDIENTE",C12,0) -> 0
I13: =IF(D13="PENDIENTE",C13,0) -> 0
I14: =IF(D14="PENDIENTE",C14,0) -> 0
... I37: =IF(D37="PENDIENTE",C37,0) -> 0

Sheet JAIME DON SADY
A1: FECHA | B1: REPUESTO | C1: PRECIO | D1: CONDICION | E1: FACTURA | F1: VENDEDOR | H1: FACTURA | I1: DEUDA | J1: TOTAL DEUDA
C2: 0 | H2: =IF(E:E="NO FACTURADO","PENDIENTE","AL DIA") -> AL DIA | I2: =IF(D2="PENDIENTE",C2,0) -> 0 | J2: =SUM(I:I) -> 0 | K2: MENU
I3: =IF(D3="PENDIENTE",C3,0) -> 0
I4: =IF(D4="PENDIENTE",C4,0) -> 0
I5: =IF(D5="PENDIENTE",C5,0) -> 0
I6: =IF(D6="PENDIENTE",C6,0) -> 0
I7: =IF(D7="PENDIENTE",C7,0) -> 0
I8: =IF(D8="PENDIENTE",C8,0) -> 0
I9: =IF(D9="PENDIENTE",C9,0) -> 0
I10: =IF(D10="PENDIENTE",C10,0) -> 0
I11: =IF(D11="PENDIENTE",C11,0) -> 0
I12: =IF(D12="PENDIENTE",C12,0) -> 0
I13: =IF(D13="PENDIENTE",C13,0) -> 0
I14: =IF(D14="PENDIENTE",C14,0) -> 0
... I37: =IF(D37="PENDIENTE",C37,0) -> 0

Sheet PAPA DE ENRIQUE ANGULO
A1: FECHA | B1: REPUESTO | C1: PRECIO | D1: CONDICION | E1: FACTURA | F1: VENDEDOR | H1: FACTURA | I1: DEUDA | J1: TOTAL DEUDA
C2: 0 | H2: =IF(E:E="NO FACTURADO","PENDIENTE","AL DIA") -> AL DIA | I2: =IF(D2="PENDIENTE",C2,0) -> 0 | J2: =SUM(I:I) -> 0 | K2: MENU
I3: =IF(D3="PENDIENTE",C3,0) -> 0
I4: =IF(D4="PENDIENTE",C4,0) -> 0
I5: =IF(D5="PENDIENTE",C5,0) -> 0
I6: =IF(D6="PENDIENTE",C6,0) -> 0
I7: =IF(D7="PENDIENTE",C7,0) -> 0
I8: =IF(D8="PENDIENTE",C8,0) -> 0
I9: =IF(D9="PENDIENTE",C9,0) -> 0
I10: =IF(D10="PENDIENTE",C10,0) -> 0
I11: =IF(D11="PENDIENTE",C11,0) -> 0
I12: =IF(D12="PENDIENTE",C12,0) -> 0
I13: =IF(D13="PENDIENTE",C13,0) -> 0
I14: =IF(D14="PENDIENTE",C14,0) -> 0
... I37: =IF(D37="PENDIENTE",C37,0) -> 0

Sheet JEREZ (CHUECO BUS NORTE)
A1: FECHA | B1: REPUESTO | C1: PRECIO | D1: CONDICION | E1: FACTURA | F1: VENDEDOR | H1: FACTURA | I1: DEUDA | J1: TOTAL DEUDA
C2: 0 | H2: =IF(E:E="NO FACTURADO","PENDIENTE","AL DIA") -> AL DIA | I2: =IF(D2="PENDIENTE",C2,0) -> 0 | J2: =SUM(I:I) -> 0 | K2: MENU
I3: =IF(D3="PENDIENTE",C3,0) -> 0
I4: =IF(D4="PENDIENTE",C4,0) -> 0
I5: =IF(D5="PENDIENTE",C5,0) -> 0
I6: =IF(D6="PENDIENTE",C6,0) -> 0
I7: =IF(D7="PENDIENTE",C7,0) -> 0
I8: =IF(D8="PENDIENTE",C8,0) -> 0
I9: =IF(D9="PENDIENTE",C9,0) -> 0
I10: =IF(D10="PENDIENTE",C10,0) -> 0
I11: =IF(D11="PENDIENTE",C11,0) -> 0
I12: =IF(D12="PENDIENTE",C12,0) -> 0
I13: =IF(D13="PENDIENTE",C13,0) -> 0
I14: =IF(D14="PENDIENTE",C14,0) -> 0
... I37: =IF(D37="PENDIENTE",C37,0) -> 0

Sheet CARDENAS TORNERO (CHICO TIO CHO
A1: FECHA | B1: REPUESTO | C1: PRECIO | D1: CONDICION | E1: FACTURA | F1: VENDEDOR | H1: FACTURA | I1: DEUDA | J1: TOTAL DEUDA
C2: 0 | H2: =IF(E:E="NO FACTURADO","PENDIENTE","AL DIA") -> AL DIA | I2: =IF(D2="PENDIENTE",C2,0) -> 0 | J2: =SUM(I:I) -> 0 | K2: MENU
I3: =IF(D3="PENDIENTE",C3,0) -> 0
I4: =IF(D4="PENDIENTE",C4,0) -> 0
I5: =IF(D5="PENDIENTE",C5,0) -> 0
I6: =IF(D6="PENDIENTE",C6,0) -> 0
I7: =IF(D7="PENDIENTE",C7,0) -> 0
I8: =IF(D8="PENDIENTE",C8,0) -> 0
I9: =IF(D9="PENDIENTE",C9,0) -> 0
I10: =IF(D10="PENDIENTE",C10,0) -> 0
I11: =IF(D11="PENDIENTE",C11,0) -> 0
I12: =IF(D12="PENDIENTE",C12,0) -> 0
I13: =IF(D13="PENDIENTE",C13,0) -> 0
I14: =IF(D14="PENDIENTE",C14,0) -> 0
... I37: =IF(D37="PENDIENTE",C37,0) -> 0

Sheet ALVARO CARRILLO
A1: FECHA | B1: REPUESTO | C1: PRECIO | D1: CONDICION | E1: FACTURA | F1: VENDEDOR | H1: FACTURA | I1: DEUDA | J1: TOTAL DEUDA
C2: 0 | H2: =IF(E:E="NO FACTURADO","PENDIENTE","AL DIA") -> AL DIA | I2: =IF(D2="PENDIENTE",C2,0) -> 0 | J2: =SUM(I:I) -> 0 | K2: MENU
I3: =IF(D3="PENDIENTE",C3,0) -> 0
I4: =IF(D4="PENDIENTE",C4,0) -> 0
I5: =IF(D5="PENDIENTE",C5,0) -> 0
I6: =IF(D6="PENDIENTE",C6,0) -> 0
I7: =IF(D7="PENDIENTE",C7,0) -> 0
I8: =IF(D8="PENDIENTE",C8,0) -> 0
I9: =IF(D9="PENDIENTE",C9,0) -> 0
I10: =IF(D10="PENDIENTE",C10,0) -> 0
I11: =IF(D11="PENDIENTE",C11,0) -> 0
I12: =IF(D12="PENDIENTE",C12,0) -> 0
I13: =IF(D13="PENDIENTE",C13,0) -> 0
I14: =IF(D14="PENDIENTE",C14,0) -> 0
... I37: =IF(D37="PENDIENTE",C37,0) -> 0

Sheet SRA NELLY FURGON
A1: FECHA | B1: REPUESTO | C1: PRECIO | D1: CONDICION | E1: FACTURA | F1: VENDEDOR | H1: FACTURA | I1: DEUDA | J1: TOTAL DEUDA
C2: 0 | H2: =IF(E:E="NO FACTURADO","PENDIENTE","AL DIA") -> AL DIA | I2: =IF(D2="PENDIENTE",C2,0) -> 0 | J2: =SUM(I:I) -> 0 | K2: MENU
I3: =IF(D3="PENDIENTE",C3,0) -> 0
I4: =IF(D4="PENDIENTE",C4,0) -> 0
I5: =IF(D5="PENDIENTE",C5,0) -> 0
I6: =IF(D6="PENDIENTE",C6,0) -> 0
I7: =IF(D7="PENDIENTE",C7,0) -> 0
I8: =IF(D8="PENDIENTE",C8,0) -> 0
I9: =IF(D9="PENDIENTE",C9,0) -> 0
I10: =IF(D10="PENDIENTE",C10,0) -> 0
I11: =IF(D11="PENDIENTE",C11,0) -> 0
I12: =IF(D12="PENDIENTE",C12,0) -> 0
I13: =IF(D13="PENDIENTE",C13,0) -> 0
I14: =IF(D14="PENDIENTE",C14,0) -> 0
... I37: =IF(D37="PENDIENTE",C37,0) -> 0

Sheet CRISTIAN SANTANA (PAILA)
A1: FECHA | B1: REPUESTO | C1: PRECIO | D1: CONDICION | E1: FACTURA | F1: VENDEDOR | H1: FACTURA | I1: DEUDA | J1: TOTAL DEUDA
C2: 0 | H2: =IF(E:E="NO FACTURADO","PENDIENTE","AL DIA") -> AL DIA | I2: =IF(D2="PENDIENTE",C2,0) -> 0 | J2: =SUM(I:I) -> 0 | K2: MENU
I3: =IF(D3="PENDIENTE",C3,0) -> 0
I4: =IF(D4="PENDIENTE",C4,0) -> 0
I5: =IF(D5="PENDIENTE",C5,0) -> 0
I6: =IF(D6="PENDIENTE",C6,0) -> 0
I7: =IF(D7="PENDIENTE",C7,0) -> 0
I8: =IF(D8="PENDIENTE",C8,0) -> 0
I9: =IF(D9="PENDIENTE",C9,0) -> 0
I10: =IF(D10="PENDIENTE",C10,0) -> 0
I11: =IF(D11="PENDIENTE",C11,0) -> 0
I12: =IF(D12="PENDIENTE",C12,0) -> 0
I13: =IF(D13="PENDIENTE",C13,0) -> 0
I14: =IF(D14="PENDIENTE",C14,0) -> 0
... I37: =IF(D37="PENDIENTE",C37,0) -> 0

Sheet CESAR CARDENAS
A1: FECHA | B1: REPUESTO | C1: PRECIO | D1: CONDICION | E1: FACTURA | F1: VENDEDOR | H1: FACTURA | I1: DEUDA | J1: TOTAL DEUDA
C2: 0 | H2: =IF(E:E="NO FACTURADO","PENDIENTE","AL DIA") -> AL DIA | I2: =IF(D2="PENDIENTE",C2,0) -> 0 | J2: =SUM(I:I) -> 0 | K2: MENU
I3: =IF(D3="PENDIENTE",C3,0) -> 0
I4: =IF(D4="PENDIENTE",C4,0) -> 0
I5: =IF(D5="PENDIENTE",C5,0) -> 0
I6: =IF(D6="PENDIENTE",C6,0) -> 0
I7: =IF(D7="PENDIENTE",C7,0) -> 0
I8: =IF(D8="PENDIENTE",C8,0) -> 0
I9: =IF(D9="PENDIENTE",C9,0) -> 0
I10: =IF(D10="PENDIENTE",C10,0) -> 0
I11: =IF(D11="PENDIENTE",C11,0) -> 0
I12: =IF(D12="PENDIENTE",C12,0) -> 0
I13: =IF(D13="PENDIENTE",C13,0) -> 0
I14: =IF(D14="PENDIENTE",C14,0) -> 0
... I37: =IF(D37="PENDIENTE",C37,0) -> 0

Sheet VICTOR GUTTIERREZ (TIO PABLO)
A1: FECHA | B1: REPUESTO | C1: PRECIO | D1: CONDICION | E1: FACTURA | F1: VENDEDOR | H1: FACTURA | I1: DEUDA | J1: TOTAL DEUDA
C2: 0 | H2: =IF(E:E="NO FACTURADO","PENDIENTE","AL DIA") -> AL DIA | I2: =IF(D2="PENDIENTE",C2,0) -> 0 | J2: =SUM(I:I) -> 0 | K2: MENU
I3: =IF(D3="PENDIENTE",C3,0) -> 0
I4: =IF(D4="PENDIENTE",C4,0) -> 0
I5: =IF(D5="PENDIENTE",C5,0) -> 0
I6: =IF(D6="PENDIENTE",C6,0) -> 0
I7: =IF(D7="PENDIENTE",C7,0) -> 0
I8: =IF(D8="PENDIENTE",C8,0) -> 0
I9: =IF(D9="PENDIENTE",C9,0) -> 0
I10: =IF(D10="PENDIENTE",C10,0) -> 0
I11: =IF(D11="PENDIENTE",C11,0) -> 0
I12: =IF(D12="PENDIENTE",C12,0) -> 0
I13: =IF(D13="PENDIENTE",C13,0) -> 0
I14: =IF(D14="PENDIENTE",C14,0) -> 0
... I37: =IF(D37="PENDIENTE",C37,0) -> 0

Sheet BORIS MANCILLA (CACHETE)
A1: FECHA | B1: REPUESTO | C1: PRECIO | D1: CONDICION | E1: FACTURA | F1: VENDEDOR | H1: FACTURA | I1: DEUDA | J1: TOTAL DEUDA
C2: 0 | H2: =IF(E:E="NO FACTURADO","PENDIENTE","AL DIA") -> AL DIA | I2: =IF(D2="PENDIENTE",C2,0) -> 0 | J2: =SUM(I:I) -> 0 | K2: MENU
I3: =IF(D3="PENDIENTE",C3,0) -> 0
I4: =IF(D4="PENDIENTE",C4,0) -> 0
I5: =IF(D5="PENDIENTE",C5,0) -> 0
I6: =IF(D6="PENDIENTE",C6,0) -> 0
I7: =IF(D7="PENDIENTE",C7,0) -> 0
I8: =IF(D8="PENDIENTE",C8,0) -> 0
I9: =IF(D9="PENDIENTE",C9,0) -> 0
I10: =IF(D10="PENDIENTE",C10,0) -> 0
I11: =IF(D11="PENDIENTE",C11,0) -> 0
I12: =IF(D12="PENDIENTE",C12,0) -> 0
I13: =IF(D13="PENDIENTE",C13,0) -> 0
I14: =IF(D14="PENDIENTE",C14,0) -> 0
... I37: =IF(D37="PENDIENTE",C37,0) -> 0

Sheet VICTOR MUÑOZ PEREZ (HUEITRA)
A1: FECHA | B1: REPUESTO | C1: PRECIO | D1: CONDICION | E1: FACTURA | F1: VENDEDOR | H1: FACTURA | I1: DEUDA | J1: TOTAL DEUDA
C2: 0 | H2: =IF(E:E="NO FACTURADO","PENDIENTE","AL DIA") -> AL DIA | I2: =IF(D2="PENDIENTE",C2,0) -> 0 | J2: =SUM(I:I) -> 0 | K2: MENU
I3: =IF(D3="PENDIENTE",C3,0) -> 0
I4: =IF(D4="PENDIENTE",C4,0) -> 0
I5: =IF(D5="PENDIENTE",C5,0) -> 0
I6: =IF(D6="PENDIENTE",C6,0) -> 0
I7: =IF(D7="PENDIENTE",C7,0) -> 0
I8: =IF(D8="PENDIENTE",C8,0) -> 0
I9: =IF(D9="PENDIENTE",C9,0) -> 0
I10: =IF(D10="PENDIENTE",C10,0) -> 0
I11: =IF(D11="PENDIENTE",C11,0) -> 0
I12: =IF(D12="PENDIENTE",C12,0) -> 0
I13: =IF(D13="PENDIENTE",C13,0) -> 0
I14: =IF(D14="PENDIENTE",C14,0) -> 0
... I37: =IF(D37="PENDIENTE",C37,0) -> 0

Sheet DON JAIME GALLARDO PUCA
A1: FECHA | B1: REPUESTO | C1: PRECIO | D1: CONDICION | E1: FACTURA | F1: VENDEDOR | H1: FACTURA | I1: DEUDA | J1: TOTAL DEUDA
C2: 0 | H2: =IF(E:E="NO FACTURADO","PENDIENTE","AL DIA") -> AL DIA | I2: =IF(D2="PENDIENTE",C2,0) -> 0 | J2: =SUM(I:I) -> 0 | K2: MENU
I3: =IF(D3="PENDIENTE",C3,0) -> 0
I4: =IF(D4="PENDIENTE",C4,0) -> 0
I5: =IF(D5="PENDIENTE",C5,0) -> 0
I6: =IF(D6="PENDIENTE",C6,0) -> 0
I7: =IF(D7="PENDIENTE",C7,0) -> 0
I8: =IF(D8="PENDIENTE",C8,0) -> 0
I9: =IF(D9="PENDIENTE",C9,0) -> 0
I10: =IF(D10="PENDIENTE",C10,0) -> 0
I11: =IF(D11="PENDIENTE",C11,0) -> 0
I12: =IF(D12="PENDIENTE",C12,0) -> 0
I13: =IF(D13="PENDIENTE",C13,0) -> 0
I14: =IF(D14="PENDIENTE",C14,0) -> 0
... I37: =IF(D37="PENDIENTE",C37,0) -> 0

Sheet ESTEBAN FARSO
A1: FECHA | B1: REPUESTO | C1: PRECIO | D1: CONDICION | E1: FACTURA | F1: VENDEDOR | H1: FACTURA | I1: DEUDA | J1: TOTAL DEUDA
C2: 0 | H2: =IF(E:E="NO FACTURADO","PENDIENTE","AL DIA") -> AL DIA | I2: =IF(D2="PENDIENTE",C2,0) -> 0 | J2: =SUM(I:I) -> 0 | K2: MENU
I3: =IF(D3="PENDIENTE",C3,0) -> 0
I4: =IF(D4="PENDIENTE",C4,0) -> 0
I5: =IF(D5="PENDIENTE",C5,0) -> 0
I6: =IF(D6="PENDIENTE",C6,0) -> 0
I7: =IF(D7="PENDIENTE",C7,0) -> 0
I8: =IF(D8="PENDIENTE",C8,0) -> 0
I9: =IF(D9="PENDIENTE",C9,0) -> 0
I10: =IF(D10="PENDIENTE",C10,0) -> 0
I11: =IF(D11="PENDIENTE",C11,0) -> 0
I12: =IF(D12="PENDIENTE",C12,0) -> 0
I13: =IF(D13="PENDIENTE",C13,0) -> 0
I14: =IF(D14="PENDIENTE",C14,0) -> 0
... I37: =IF(D37="PENDIENTE",C37,0) -> 0

Sheet MANUEL VILLA 
A1: FECHA | B1: REPUESTO | C1: PRECIO | D1: CONDICION | E1: FACTURA | F1: VENDEDOR | H1: FACTURA | I1: DEUDA | J1: TOTAL DEUDA
C2: 0 | H2: =IF(E:E="NO FACTURADO","PENDIENTE","AL DIA") -> AL DIA | I2: =IF(D2="PENDIENTE",C2,0) -> 0 | J2: =SUM(I:I) -> 0 | K2: MENU
I3: =IF(D3="PENDIENTE",C3,0) -> 0
I4: =IF(D4="PENDIENTE",C4,0) -> 0
I5: =IF(D5="PENDIENTE",C5,0) -> 0
I6: =IF(D6="PENDIENTE",C6,0) -> 0
I7: =IF(D7="PENDIENTE",C7,0) -> 0
I8: =IF(D8="PENDIENTE",C8,0) -> 0
I9: =IF(D9="PENDIENTE",C9,0) -> 0
I10: =IF(D10="PENDIENTE",C10,0) -> 0
I11: =IF(D11="PENDIENTE",C11,0) -> 0
I12: =IF(D12="PENDIENTE",C12,0) -> 0
I13: =IF(D13="PENDIENTE",C13,0) -> 0
I14: =IF(D14="PENDIENTE",C14,0) -> 0
... I37: =IF(D37="PENDIENTE",C37,0) -> 0

Sheet VECINO GAS MOLL
A1: FECHA | B1: REPUESTO | C1: PRECIO | D1: CONDICION | E1: FACTURA | F1: VENDEDOR | H1: FACTURA | I1: DEUDA | J1: TOTAL DEUDA
C2: 0 | H2: =IF(E:E="NO FACTURADO","PENDIENTE","AL DIA") -> AL DIA | I2: =IF(D2="PENDIENTE",C2,0) -> 0 | J2: =SUM(I:I) -> 0 | K2: MENU
I3: =IF(D3="PENDIENTE",C3,0) -> 0
I4: =IF(D4="PENDIENTE",C4,0) -> 0
I5: =IF(D5="PENDIENTE",C5,0) -> 0
I6: =IF(D6="PENDIENTE",C6,0) -> 0
I7: =IF(D7="PENDIENTE",C7,0) -> 0
I8: =IF(D8="PENDIENTE",C8,0) -> 0
I9: =IF(D9="PENDIENTE",C9,0) -> 0
I10: =IF(D10="PENDIENTE",C10,0) -> 0
I11: =IF(D11="PENDIENTE",C11,0) -> 0
I12: =IF(D12="PENDIENTE",C12,0) -> 0
I13: =IF(D13="PENDIENTE",C13,0) -> 0
I14: =IF(D14="PENDIENTE",C14,0) -> 0
... I37: =IF(D37="PENDIENTE",C37,0) -> 0

Sheet PAPA DE GUILLE
A1: FECHA | B1: REPUESTO | C1: PRECIO | D1: CONDICION | E1: FACTURA | F1: VENDEDOR | H1: FACTURA | I1: DEUDA | J1: TOTAL DEUDA
H2: =IF(E:E="NO FACTURADO","PENDIENTE","AL DIA") -> AL DIA | I2: =IF(D2="PENDIENTE",C2,0) -> 0 | J2: =SUM(I:I) -> 0 | K2: MENU
I3: =IF(D3="PENDIENTE",C3,0) -> 0
I4: =IF(D4="PENDIENTE",C4,0) -> 0
I5: =IF(D5="PENDIENTE",C5,0) -> 0
I6: =IF(D6="PENDIENTE",C6,0) -> 0
I7: =IF(D7="PENDIENTE",C7,0) -> 0
I8: =IF(D8="PENDIENTE",C8,0) -> 0
I9: =IF(D9="PENDIENTE",C9,0) -> 0
I10: =IF(D10="PENDIENTE",C10,0) -> 0
I11: =IF(D11="PENDIENTE",C11,0) -> 0
I12: =IF(D12="PENDIENTE",C12,0) -> 0
I13: =IF(D13="PENDIENTE",C13,0) -> 0
I14: =IF(D14="PENDIENTE",C14,0) -> 0
... I37: =IF(D37="PENDIENTE",C37,0) -> 0

Sheet SEGOVIA GUILLERMO
A1: FECHA | B1: REPUESTO | C1: PRECIO | D1: CONDICION | E1: FACTURA | F1: VENDEDOR | H1: FACTURA | I1: DEUDA | J1: TOTAL DEUDA
H2: =IF(E:E="NO FACTURADO","PENDIENTE","AL DIA") -> AL DIA | I2: =IF(D2="PENDIENTE",C2,0) -> 0 | J2: =SUM(I:I) -> 0 | K2: MENU
A3: 02/0572023 | B3: SALDO BATERIA S10 | C3: 80000 | D3: PAGADO | F3: DELIS | I3: =IF(D3="PENDIENTE",C3,0) -> 0
I4: =IF(D4="PENDIENTE",C4,0) -> 0
I5: =IF(D5="PENDIENTE",C5,0) -> 0
I6: =IF(D6="PENDIENTE",C6,0) -> 0
I7: =IF(D7="PENDIENTE",C7,0) -> 0
I8: =IF(D8="PENDIENTE",C8,0) -> 0
I9: =IF(D9="PENDIENTE",C9,0) -> 0
I10: =IF(D10="PENDIENTE",C10,0) -> 0
I11: =IF(D11="PENDIENTE",C11,0) -> 0
I12: =IF(D12="PENDIENTE",C12,0) -> 0
I13: =IF(D13="PENDIENTE",C13,0) -> 0
I14: =IF(D14="PENDIENTE",C14,0) -> 0
I15: =IF(D15="PENDIENTE",C15,0) -> 0
... I37: =IF(D37="PENDIENTE",C37,0) -> 0

Sheet FERNANDEZ NICASIO (TIO CABALLO)
A1: FECHA | B1: REPUESTO | C1: PRECIO | D1: CONDICION | E1: FACTURA | F1: VENDEDOR | H1: FACTURA | I1: DEUDA | J1: TOTAL DEUDA
H2: =IF(E:E="NO FACTURADO","PENDIENTE","AL DIA") -> AL DIA | I2: =IF(D2="PENDIENTE",C2,0) -> 0 | J2: =SUM(I:I) -> 0 | K2: MENU
A3: 45044 | B3: CREMALLERA DIRECCION DMAX | C3: 185000 | D3: pagado | I3: =IF(D3="PENDIENTE",C3,0) -> 0
A4: 45044 | B4: ATF | C4: 7500 | D4: pagado | I4: =IF(D4="PENDIENTE",C4,0) -> 0
A5: 45379 | B5: saldo kit embrague | C5: 50000 | D5: pagado | E5: pagado | I5: =IF(E5="PENDIENTE",C5,0) -> 0
A6: 45527 | B6: REPUESTOS LUV 2,2 | C6: 40000 | D6: pagado | E6: abono $50000 25/09 | I6: =IF(D6="PENDIENTE",C6,0) -> 0
A7: 45533 | B7: EJE LEVA BALANCIN | C7: 121000 | D7: pagado | I7: =IF(D7="PENDIENTE",C7,0) -> 0
I8: =IF(D8="PENDIENTE",C8,0) -> 0
I9: =IF(D9="PENDIENTE",C9,0) -> 0
I10: =IF(D10="PENDIENTE",C10,0) -> 0
I11: =IF(D11="PENDIENTE",C11,0) -> 0
I12: =IF(D12="PENDIENTE",C12,0) -> 0
I13: =IF(D13="PENDIENTE",C13,0) -> 0
I14: =IF(D14="PENDIENTE",C14,0) -> 0
I15: =IF(D15="PENDIENTE",C15,0) -> 0
I16: =IF(D16="PENDIENTE",C16,0) -> 0
I17: =IF(D17="PENDIENTE",C17,0) -> 0
I18: =IF(D18="PENDIENTE",C18,0) -> 0
I19: =IF(D19="PENDIENTE",C19,0) -> 0
... I37: =IF(D37="PENDIENTE",C37,0) -> 0

Sheet TIO CABALLO
A1: FECHA | B1: REPUESTO | C1: PRECIO | D1: CONDICION | E1: FACTURA | F1: VENDEDOR | H1: FACTURA | I1: DEUDA | J1: TOTAL DEUDA
A2: 45065 | B2: saldo cremallera | C2: 27000 | D2: pagado | H2: =IF(E:E="NO FACTURADO","PENDIENTE","AL DIA") -> AL DIA | I2: =IF(D2="PENDIENTE",C2,0) -> 0 | J2: =SUM(I:I) -> 112000 | K2: MENU
A3: 45170 | B3: saldo optico | C3: 15000 | D3: pagado | I3: =IF(D3="PENDIENTE",C3,0) -> 0
B4: TAMBOR FRENO PATINES | C4: 95000 | D4: pagado | I4: =IF(D4="PENDIENTE",C4,0) -> 0
A5: 45358 | B5: kit embrague | C5: 85000 | D5: pagado | I5: =IF(D5="PENDIENTE",C5,0) -> 0
A6: 45415 | B6: BATERIA 90AMPERES POSITIVO LH | C6: 110000 | D6: pagado | I6: =IF(D6="PENDIENTE",C6,0) -> 0
A7: 45608 | B7: pistones caliper x2 | C7: 50000 | D7: pagado | I7: =IF(D7="PENDIENTE",C7,0) -> 0
A8: 45609 | B8: jgo rodamiento maza x2 | C8: 90000 | D8: pagado | I8: =IF(D8="PENDIENTE",C8,0) -> 0
A9: 45609 | B9: homocinetica x1 | C9: 20000 | D9: pendiente | E9: abono $160000 | I9: =IF(D9="PENDIENTE",C9,0) -> 20000
A10: 45609 | B10: rotula inferior x2 | C10: 64000 | D10: pendiente | I10: =IF(D10="PENDIENTE",C10,0) -> 64000
A11: 45602 | B11: repuesto | C11: 28000 | D11: pendiente | I11: =IF(D11="PENDIENTE",C11,0) -> 28000
I12: =IF(D12="PENDIENTE",C12,0) -> 0
I13: =IF(D13="PENDIENTE",C13,0) -> 0
I14: =IF(D14="PENDIENTE",C14,0) -> 0
I15: =IF(D15="PENDIENTE",C15,0) -> 0
I16: =IF(D16="PENDIENTE",C16,0) -> 0
I17: =IF(D17="PENDIENTE",C17,0) -> 0
I18: =IF(D18="PENDIENTE",C18,0) -> 0
I19: =IF(D19="PENDIENTE",C19,0) -> 0
I20: =IF(D20="PENDIENTE",C20,0) -> 0
I21: =IF(D21="PENDIENTE",C21,0) -> 0
I22: =IF(D22="PENDIENTE",C22,0) -> 0
I23: =IF(D23="PENDIENTE",C23,0) -> 0
... I37: =IF(D37="PENDIENTE",C37,0) -> 0

Sheet PAREDES JUAN (PERRITO)
A1: FECHA | B1: REPUESTO | C1: PRECIO | D1: CONDICION | E1: FACTURA | F1: VENDEDOR | H1: FACTURA | I1: DEUDA | J1: TOTAL DEUDA
A2: 44753 | B2: cilindro freno y liquido | C2: 30000 | D2: PAGADO | F2: delis | H2: =IF(E:E="NO FACTURADO","PENDIENTE","AL DIA") -> AL DIA | I2: =IF(D2="PENDIENTE",C2,0) -> 0 | J2: =SUM(I:I) -> 0 | K2: MENU
A3: 45112 | B3: ACEITE SHELL X2 CATALITICO | C3: 120000 | D3: PAGADO | F3: CESAR | I3: =IF(D3="PENDIENTE",C3,0) -> 0
I4: =IF(D4="PENDIENTE",C4,0) -> 0
I5: =IF(D5="PENDIENTE",C5,0) -> 0
I6: =IF(D6="PENDIENTE",C6,0) -> 0
I7: =IF(D7="PENDIENTE",C7,0) -> 0
I8: =IF(D8="PENDIENTE",C8,0) -> 0
I9: =IF(D9="PENDIENTE",C9,0) -> 0
I10: =IF(D10="PENDIENTE",C10,0) -> 0
I11: =IF(D11="PENDIENTE",C11,0) -> 0
I12: =IF(D12="PENDIENTE",C12,0) -> 0
I13: =IF(D13="PENDIENTE",C13,0) -> 0
I14: =IF(D14="PENDIENTE",C14,0) -> 0
I15: =IF(D15="PENDIENTE",C15,0) -> 0
... I37: =IF(D37="PENDIENTE",C37,0) -> 0

Sheet PALMA ROSAS JUAN  (VITOY)
A1: FECHA | B1: REPUESTO | C1: PRECIO | D1: CONDICION | E1: FACTURA | F1: VENDEDOR | H1: FACTURA | I1: DEUDA | J1: TOTAL DEUDA
A2: 44852 | B2: BATERIA 55 AMP | C2: 50000 | D2: PAGADO | F2: CESAR | H2: =IF(E:E="NO FACTURADO","PENDIENTE","AL DIA") -> AL DIA | I2: =IF(D2="PENDIENTE",C2,0) -> 0 | J2: =SUM(I:I) -> 0 | K2: MENU
A3: 44902 | B3: OPTICO CORSA LH | C3: 30000 | D3: PAGADO | F3: DELIS | I3: =IF(D3="PENDIENTE",C3,0) -> 0
A4: 45224 | B4: KIT EMBRAGUE | C4: 130000 | D4: PAGADO | F4: DELIS | I4: =IF(D4="PENDIENTE",C4,0) -> 0
A5: 45265 | B5: PATINES Y PASTILLA FRENO | C5: 46000 | D5: PAGADO | I5: =IF(D5="PENDIENTE",C5,0) -> 0
A6: 44937 | B6: bandeja accent 2018 | C6: 52000 | D6: PAGADO | I6: =IF(D6="PENDIENTE",C6,0) -> 0
I7: =IF(D7="PENDIENTE",C7,0) -> 0
I8: =IF(D8="PENDIENTE",C8,0) -> 0
I9: =IF(D9="PENDIENTE",C9,0) -> 0
I10: =IF(D10="PENDIENTE",C10,0) -> 0
I11: =IF(D11="PENDIENTE",C11,0) -> 0
I12: =IF(D12="PENDIENTE",C12,0) -> 0
I13: =IF(D13="PENDIENTE",C13,0) -> 0
I14: =IF(D14="PENDIENTE",C14,0) -> 0
I15: =IF(D15="PENDIENTE",C15,0) -> 0
I16: =IF(D16="PENDIENTE",C16,0) -> 0
I17: =IF(D17="PENDIENTE",C17,0) -> 0
I18: =IF(D18="PENDIENTE",C18,0) -> 0
... I37: =IF(D37="PENDIENTE",C37,0) -> 0

Sheet CORONADO LORENA
A1: FECHA | B1: REPUESTO | C1: PRECIO | D1: CONDICION | E1: FACTURA | F1: VENDEDOR | H1: FACTURA | I1: DEUDA | J1: TOTAL DEUDA
A2: 44894 | B2: saldo repuestos | C2: 100000 | D2: pagado | F2: delis | H2: =IF(E:E="NO FACTURADO","PENDIENTE","AL DIA") -> AL DIA | I2: =IF(D2="PENDIENTE",C2,0) -> 0 | J2: =SUM(I:I) -> 0 | K2: MENU
A3: 44945 | B3: SALDO REPUESTOS BATERIA PASTILLA LIQU FRENO | C3: 59500 | D3: pagado | F3: DELIS | I3: =IF(D3="PENDIENTE",C3,0) -> 0
A4: 44992 | B4: bateria filtro aire foco carro | C4: 65000 | D4: PAGADO | F4: cesar | I4: =IF(D4="PENDIENTE",C4,0) -> 0
A5: 45077 | B5: pastilla d21 + liquido freno senfineco | C5: 21500 | D5: PAGADO | F5: omar | I5: =IF(D5="PENDIENTE",C5,0) -> 0
A6: 45146 | B6: amortiguadores traseros kia | C6: 80000 | D6: PAGADO | F6: cesar | I6: =IF(D6="PENDIENTE",C6,0) -> 0
A7: 45217 | B7: AMORTIGUADORES DELANTEROS BUJES Y PTA | C7: 15000 | D7: PAGADO | F7: DELIS | I7: =IF(D7="PENDIENTE",C7,0) -> 0
A8: 45225 | B8: bomba embrague y liquido freno | C8: 38500 | D8: PAGADO | F8: cesar | I8: =IF(D8="PENDIENTE",C8,0) -> 0
A9: 45331 | B9: pastillas de frenos kia | C9: 20000 | D9: pagado | I9: =IF(D9="PENDIENTE",C9,0) -> 0
A10: 45446 | B10: PRESUPUESTO 6213 | C10: 420000 | D10: pagado | E10: ABONO $150000 | I10: =IF(D10="PENDIENTE",C10,0) -> 0
A11: 45471 | B11: filtro aire y bornes bateria | C11: 16000 | D11: pagado | I11: =IF(D11="PENDIENTE",C11,0) -> 0
I12: =IF(D12="PENDIENTE",C12,0) -> 0
I13: =IF(D13="PENDIENTE",C13,0) -> 0
I14: =IF(D14="PENDIENTE",C14,0) -> 0
I15: =IF(D15="PENDIENTE",C15,0) -> 0
I16: =IF(D16="PENDIENTE",C16,0) -> 0
I17: =IF(D17="PENDIENTE",C17,0) -> 0
I18: =IF(D18="PENDIENTE",C18,0) -> 0
I19: =IF(D19="PENDIENTE",C19,0) -> 0
I20: =IF(D20="PENDIENTE",C20,0) -> 0
I21: =IF(D21="PENDIENTE",C21,0) -> 0
I22: =IF(D22="PENDIENTE",C22,0) -> 0
I23: =IF(D23="PENDIENTE",C23,0) -> 0
... I37: =IF(D37="PENDIENTE",C37,0) -> 0

Sheet MAESTRO GODOY  CACHITO
A1: FECHA | B1: REPUESTO | C1: PRECIO | D1: CONDICION | E1: FACTURA | F1: VENDEDOR | H1: FACTURA | I1: DEUDA | J1: TOTAL DEUDA
C2: 15000 | D2: PENDIENTE | H2: =IF(E:E="NO FACTURADO","PENDIENTE","AL DIA") -> AL DIA | I2: =IF(D2="PENDIENTE",C2,0) -> 15000 | J2: =SUM(I:I) -> 15000 | K2: MENU
I3: =IF(D3="PENDIENTE",C3,0) -> 0
I4: =IF(D4="PENDIENTE",C4,0) -> 0
I5: =IF(D5="PENDIENTE",C5,0) -> 0
I6: =IF(D6="PENDIENTE",C6,0) -> 0
I7: =IF(D7="PENDIENTE",C7,0) -> 0
I8: =IF(D8="PENDIENTE",C8,0) -> 0
I9: =IF(D9="PENDIENTE",C9,0) -> 0
I10: =IF(D10="PENDIENTE",C10,0) -> 0
I11: =IF(D11="PENDIENTE",C11,0) -> 0
I12: =IF(D12="PENDIENTE",C12,0) -> 0
I13: =IF(D13="PENDIENTE",C13,0) -> 0
I14: =IF(D14="PENDIENTE",C14,0) -> 0
... I37: =IF(D37="PENDIENTE",C37,0) -> 0

Sheet NAGIAN BERNARDO 
A1: FECHA | B1: REPUESTO | C1: PRECIO | D1: CONDICION | E1: FACTURA | F1: VENDEDOR | H1: FACTURA | I1: DEUDA | J1: TOTAL DEUDA
H2: =IF(E:E="NO FACTURADO","PENDIENTE","AL DIA") -> AL DIA | I2: =IF(D2="PENDIENTE",C2,0) -> 0 | J2: =SUM(I:I) -> 0 | K2: MENU
I3: =IF(D3="PENDIENTE",C3,0) -> 0
I4: =IF(D4="PENDIENTE",C4,0) -> 0
I5: =IF(D5="PENDIENTE",C5,0) -> 0
I6: =IF(D6="PENDIENTE",C6,0) -> 0
I7: =IF(D7="PENDIENTE",C7,0) -> 0
I8: =IF(D8="PENDIENTE",C8,0) -> 0
I9: =IF(D9="PENDIENTE",C9,0) -> 0
I10: =IF(D10="PENDIENTE",C10,0) -> 0
I11: =IF(D11="PENDIENTE",C11,0) -> 0
I12: =IF(D12="PENDIENTE",C12,0) -> 0
I13: =IF(D13="PENDIENTE",C13,0) -> 0
I14: =IF(D14="PENDIENTE",C14,0) -> 0
... I37: =IF(D37="PENDIENTE",C37,0) -> 0

Sheet TIO OMAR
A1: FECHA | B1: REPUESTO | C1: PRECIO | D1: CONDICION | E1: FACTURA | F1: VENDEDOR | H1: FACTURA | I1: DEUDA | J1: TOTAL DEUDA
D2: pendiente | H2: =IF(E:E="NO FACTURADO","PENDIENTE","AL DIA") -> AL DIA | I2: =IF(D2="PENDIENTE",C2,0) -> 0 | J2: =SUM(I:I) -> 0 | K2: MENU
A3: 45107 | B3: filtro aire y cabina | C3: 10000 | D3: pagado | F3: delis | I3: =IF(D3="PENDIENTE",C3,0) -> 0
A4: 45348 | B4: cazoleta delantera derecha | C4: 18000 | D4: pagado | I4: =IF(D4="PENDIENTE",C4,0) -> 0
A5: 45436 | B5: filtro cabina | C5: 5000 | D5: pagado | I5: =IF(D5="PENDIENTE",C5,0) -> 0
I6: =IF(D6="PENDIENTE",C6,0) -> 0
I7: =IF(D7="PENDIENTE",C7,0) -> 0
I8: =IF(D8="PENDIENTE",C8,0) -> 0
I9: =IF(D9="PENDIENTE",C9,0) -> 0
I10: =IF(D10="PENDIENTE",C10,0) -> 0
I11: =IF(D11="PENDIENTE",C11,0) -> 0
I12: =IF(D12="PENDIENTE",C12,0) -> 0
I13: =IF(D13="PENDIENTE",C13,0) -> 0
I14: =IF(D14="PENDIENTE",C14,0) -> 0
I15: =IF(D15="PENDIENTE",C15,0) -> 0
I16: =IF(D16="PENDIENTE",C16,0) -> 0
I17: =IF(D17="PENDIENTE",C17,0) -> 0
... I37: =IF(D37="PENDIENTE",C37,0) -> 0

Sheet AROS MARCIA
A1: FECHA | B1: REPUESTO | C1: PRECIO | D1: CONDICION | E1: FACTURA | F1: VENDEDOR | H1: FACTURA | I1: DEUDA | J1: TOTAL DEUDA
H2: =IF(E:E="NO FACTURADO","PENDIENTE","AL DIA") -> AL DIA | I2: =IF(D2="PENDIENTE",C2,0) -> 0 | J2: =SUM(I:I) -> 0 | K2: MENU
I3: =IF(D3="PENDIENTE",C3,0) -> 0
I4: =IF(D4="PENDIENTE",C4,0) -> 0
I5: =IF(D5="PENDIENTE",C5,0) -> 0
I6: =IF(D6="PENDIENTE",C6,0) -> 0
I7: =IF(D7="PENDIENTE",C7,0) -> 0
I8: =IF(D8="PENDIENTE",C8,0) -> 0
I9: =IF(D9="PENDIENTE",C9,0) -> 0
I10: =IF(D10="PENDIENTE",C10,0) -> 0
I11: =IF(D11="PENDIENTE",C11,0) -> 0
I12: =IF(D12="PENDIENTE",C12,0) -> 0
I13: =IF(D13="PENDIENTE",C13,0) -> 0
I14: =IF(D14="PENDIENTE",C14,0) -> 0
... I37: =IF(D37="PENDIENTE",C37,0) -> 0

Sheet TOSKA
A1: FECHA | B1: REPUESTO | C1: PRECIO | D1: CONDICION | E1: FACTURA | F1: VENDEDOR | H1: FACTURA | I1: DEUDA | J1: TOTAL DEUDA
H2: =IF(E:E="NO FACTURADO","PENDIENTE","AL DIA") -> AL DIA | I2: =IF(D2="PENDIENTE",C2,0) -> 0 | J2: =SUM(I:I) -> 0 | K2: MENU
A3: 45072 | B3: farol kia | C3: 48000 | D3: PAGADO | F3: cesar | I3: =IF(D3="PENDIENTE",C3,0) -> 0
I4: =IF(D4="PENDIENTE",C4,0) -> 0
I5: =IF(D5="PENDIENTE",C5,0) -> 0
I6: =IF(D6="PENDIENTE",C6,0) -> 0
I7: =IF(D7="PENDIENTE",C7,0) -> 0
I8: =IF(D8="PENDIENTE",C8,0) -> 0
I9: =IF(D9="PENDIENTE",C9,0) -> 0
I10: =IF(D10="PENDIENTE",C10,0) -> 0
I11: =IF(D11="PENDIENTE",C11,0) -> 0
I12: =IF(D12="PENDIENTE",C12,0) -> 0
I13: =IF(D13="PENDIENTE",C13,0) -> 0
I14: =IF(D14="PENDIENTE",C14,0) -> 0
I15: =IF(D15="PENDIENTE",C15,0) -> 0
... I37: =IF(D37="PENDIENTE",C37,0) -> 0

Sheet CLIENTE NUEVO
A1: FECHA | B1: REPUESTO | C1: PRECIO | D1: CONDICION | E1: FACTURA | F1: VENDEDOR | H1: FACTURA | I1: DEUDA | J1: TOTAL DEUDA
H2: =IF(E:E="NO FACTURADO","PENDIENTE","AL DIA") -> AL DIA | I2: =IF(D2="PENDIENTE",C2,0) -> 0 | J2: =SUM(I:I) -> 0 | K2: MENU
I3: =IF(D3="PENDIENTE",C3,0) -> 0
I4: =IF(D4="PENDIENTE",C4,0) -> 0
I5: =IF(D5="PENDIENTE",C5,0) -> 0
I6: =IF(D6="PENDIENTE",C6,0) -> 0
I7: =IF(D7="PENDIENTE",C7,0) -> 0
I8: =IF(D8="PENDIENTE",C8,0) -> 0
I9: =IF(D9="PENDIENTE",C9,0) -> 0
I10: =IF(D10="PENDIENTE",C10,0) -> 0
I11: =IF(D11="PENDIENTE",C11,0) -> 0
I12: =IF(D12="PENDIENTE",C12,0) -> 0
I13: =IF(D13="PENDIENTE",C13,0) -> 0
I14: =IF(D14="PENDIENTE",C14,0) -> 0
... I37: =IF(D37="PENDIENTE",C37,0) -> 0

Sheet CHICO JULIO
A1: FECHA | B1: REPUESTO | C1: PRECIO | D1: CONDICION | E1: FACTURA | F1: VENDEDOR | H1: FACTURA | I1: DEUDA | J1: TOTAL DEUDA
B2: SALDO | C2: 12000 | D2: PENDIENTE | F2: DELIS | H2: =IF(E:E="NO FACTURADO","PENDIENTE","AL DIA") -> AL DIA | I2: =IF(D2="PENDIENTE",C2,0) -> 12000 | J2: =SUM(I:I) -> 12000 | K2: MENU
I3: =IF(D3="PENDIENTE",C3,0) -> 0
I4: =IF(D4="PENDIENTE",C4,0) -> 0
I5: =IF(D5="PENDIENTE",C5,0) -> 0
I6: =IF(D6="PENDIENTE",C6,0) -> 0
I7: =IF(D7="PENDIENTE",C7,0) -> 0
I8: =IF(D8="PENDIENTE",C8,0) -> 0
I9: =IF(D9="PENDIENTE",C9,0) -> 0
I10: =IF(D10="PENDIENTE",C10,0) -> 0
I11: =IF(D11="PENDIENTE",C11,0) -> 0
I12: =IF(D12="PENDIENTE",C12,0) -> 0
I13: =IF(D13="PENDIENTE",C13,0) -> 0
I14: =IF(D14="PENDIENTE",C14,0) -> 0
... I37: =IF(D37="PENDIENTE",C37,0) -> 0

Sheet FELIPE AGUILAR (BULLA) LICAN
A1: FECHA | B1: REPUESTO | C1: PRECIO | D1: CONDICION | E1: FACTURA | F1: VENDEDOR | H1: FACTURA | I1: DEUDA | J1: TOTAL DEUDA
A2: 44638 | B2: AMPOLLETAS | C2: 3000 | D2: PAGADO | E2: no factura | F2: CESAR | H2: =IF(E:E="NO FACTURADO","PENDIENTE","AL DIA") -> AL DIA | I2: =IF(D2="PENDIENTE",C2,0) -> 0 | J2: =SUM(I:I) -> 0 | K2: MENU
A3: 44648 | B3: silicona | C3: 7000 | D3: PAGADO | E3: no factura | F3: CESAR | I3: =IF(D3="PENDIENTE",C3,0) -> 0
A4: 44665 | B4: AMPOLLETAS | C4: 4000 | D4: PAGADO | F4: CESAR | I4: =IF(D4="PENDIENTE",C4,0) -> 0
A5: 44704 | B5: MANTENCIAN KUN | C5: 98000 | D5: PAGADO | I5: =IF(D5="PENDIENTE",C5,0) -> 0
A6: 44711 | B6: amortiguadores trasero kun | C6: 100000 | D6: PAGADO | I6: =IF(D6="PENDIENTE",C6,0) -> 0
A7: 44750 | B7: kit embrague kun santa clara lican | C7: 458000 | D7: PAGADO | F7: CESAR | I7: =IF(D7="PENDIENTE",C7,0) -> 0
A8: 44665 | B8: bilomoide | C8: 4000 | D8: PAGADO | F8: omar | I8: =IF(D8="PENDIENTE",C8,0) -> 0
A9: 44764 | B9: FILTRO COMBUSTIBLE | C9: 10000 | D9: PAGADO | F9: CESAR | I9: =IF(D9="PENDIENTE",C9,0) -> 0
A10: 44767 | B10: aceite 75w90 gl5 3lts | C10: 43500 | D10: PAGADO | F10: CESAR | I10: =IF(D10="PENDIENTE",C10,0) -> 0
A11: 44795 | B11: ROTULA SUPERIOR | C11: 22000 | D11: PAGADO | F11: CESAR | I11: =IF(D11="PENDIENTE",C11,0) -> 0
A12: 44795 | B12: JGO PASTILLA FRENO | C12: 20000 | D12: PAGADO | F12: CESAR | I12: =IF(D12="PENDIENTE",C12,0) -> 0
A13: 44796 | B13: cilindro freno + bliquido freno | C13: 25000 | D13: PAGADO | F13: CESAR | I13: =IF(D13="PENDIENTE",C13,0) -> 0
A14: 44798 | B14: limpiador freno | C14: 12000 | D14: PAGADO | F14: CESAR | I14: =IF(D14="PENDIENTE",C14,0) -> 0
A15: 44809 | B15: silicona y ampolleta | C15: 7000 | D15: PAGADO | F15: CESAR | I15: =IF(D15="PENDIENTE",C15,0) -> 0
A16: 44826 | B16: RADIADOR CALEFA + FUELLE | C16: 72000 | D16: PAGADO | F16: CESAR | I16: =IF(D16="PENDIENTE",C16,0) -> 0
A17: 44854 | B17: cruceta + aceite 75w90 | C17: 53000 | D17: PAGADO | F17: CESAR | I17: =IF(D17="PENDIENTE",C17,0) -> 0
A18: 44874 | B18: cambio aceite 4n15 | C18: 150000 | D18: pAGADO | F18: CESAR | I18: =IF(D18="PENDIENTE",C18,0) -> 0
... A24: 45215 | B24: 75w90 gl5 3lts | C24: 40500 | D24: pAGADO | F24: CESAR | I24: =IF(D24="PENDIENTE",C24,0) -> 0
I25: =IF(D25="PENDIENTE",C25,0) -> 0
I26: =IF(D26="PENDIENTE",C26,0) -> 0
I27: =IF(D27="PENDIENTE",C27,0) -> 0
I28: =IF(D28="PENDIENTE",C28,0) -> 0
I29: =IF(D29="PENDIENTE",C29,0) -> 0
I30: =IF(D30="PENDIENTE",C30,0) -> 0
I31: =IF(D31="PENDIENTE",C31,0) -> 0
I32: =IF(D32="PENDIENTE",C32,0) -> 0
I33: =IF(D33="PENDIENTE",C33,0) -> 0
I34: =IF(D34="PENDIENTE",C34,0) -> 0
I35: =IF(D35="PENDIENTE",C35,0) -> 0
I36: =IF(D36="PENDIENTE",C36,0) -> 0

Sheet FUENTES HECTOR
A1: FECHA | B1: REPUESTO | C1: PRECIO | D1: CONDICION | E1: FACTURA | F1: VENDEDOR | H1: FACTURA | I1: DEUDA | J1: TOTAL DEUDA
H2: =IF(E:E="NO FACTURADO","PENDIENTE","AL DIA") -> AL DIA | I2: =IF(D2="PENDIENTE",C2,0) -> 0 | J2: =SUM(I:I) -> 0 | K2: MENU
A3: 44623 | B3: PRESUPUESTO Nº 4830 SOBRINO | C3: 592000 | D3: pagado | E3: facturado | F3: DELIS | I3: =IF(D3="PENDIENTE",C3,0) -> 0
I4: =IF(D4="PENDIENTE",C4,0) -> 0
I5: =IF(D5="PENDIENTE",C5,0) -> 0
I6: =IF(D6="PENDIENTE",C6,0) -> 0
I7: =IF(D7="PENDIENTE",C7,0) -> 0
I8: =IF(D8="PENDIENTE",C8,0) -> 0
I9: =IF(D9="PENDIENTE",C9,0) -> 0
I10: =IF(D10="PENDIENTE",C10,0) -> 0
I11: =IF(D11="PENDIENTE",C11,0) -> 0
I12: =IF(D12="PENDIENTE",C12,0) -> 0
I13: =IF(D13="PENDIENTE",C13,0) -> 0
I14: =IF(D14="PENDIENTE",C14,0) -> 0
I15: =IF(D15="PENDIENTE",C15,0) -> 0
... I37: =IF(D37="PENDIENTE",C37,0) -> 0

Sheet LOAIZA JOSE(FRANKE)
A1: FECHA | B1: REPUESTO | C1: PRECIO | D1: CONDICION | E1: FACTURA | F1: VENDEDOR | H1: FACTURA | I1: DEUDA | J1: TOTAL DEUDA
H2: =IF(E:E="NO FACTURADO","PENDIENTE","AL DIA") -> AL DIA | I2: =IF(D2="PENDIENTE",C2,0) -> 0 | J2: =SUM(I:I) -> 0 | K2: MENU
I3: =IF(D3="PENDIENTE",C3,0) -> 0
I4: =IF(D4="PENDIENTE",C4,0) -> 0
I5: =IF(D5="PENDIENTE",C5,0) -> 0
I6: =IF(D6="PENDIENTE",C6,0) -> 0
I7: =IF(D7="PENDIENTE",C7,0) -> 0
I8: =IF(D8="PENDIENTE",C8,0) -> 0
I9: =IF(D9="PENDIENTE",C9,0) -> 0
I10: =IF(D10="PENDIENTE",C10,0) -> 0
I11: =IF(D11="PENDIENTE",C11,0) -> 0
I12: =IF(D12="PENDIENTE",C12,0) -> 0
I13: =IF(D13="PENDIENTE",C13,0) -> 0
I14: =IF(D14="PENDIENTE",C14,0) -> 0
... I37: =IF(D37="PENDIENTE",C37,0) -> 0

Sheet LORCA EMERSON
A1: FECHA | B1: REPUESTO | C1: PRECIO | D1: CONDICION | E1: FACTURA | F1: VENDEDOR | H1: FACTURA | I1: DEUDA | J1: TOTAL DEUDA
A2: 44384 | C2: 42000 | D2: PENDIENTE | H2: =IF(E:E="NO FACTURADO","PENDIENTE","AL DIA") -> AL DIA | I2: =IF(D2="PENDIENTE",C2,0) -> 42000 | J2: =SUM(I:I) -> 56000 | K2: MENU
A3: 44545 | B3: mas 14000 del 15/12 | C3: 14000 | D3: PENDIENTE | I3: =IF(D3="PENDIENTE",C3,0) -> 14000
I4: =IF(D4="PENDIENTE",C4,0) -> 0
I5: =IF(D5="PENDIENTE",C5,0) -> 0
I6: =IF(D6="PENDIENTE",C6,0) -> 0
I7: =IF(D7="PENDIENTE",C7,0) -> 0
I8: =IF(D8="PENDIENTE",C8,0) -> 0
I9: =IF(D9="PENDIENTE",C9,0) -> 0
I10: =IF(D10="PENDIENTE",C10,0) -> 0
I11: =IF(D11="PENDIENTE",C11,0) -> 0
I12: =IF(D12="PENDIENTE",C12,0) -> 0
I13: =IF(D13="PENDIENTE",C13,0) -> 0
I14: =IF(D14="PENDIENTE",C14,0) -> 0
I15: =IF(D15="PENDIENTE",C15,0) -> 0
... I37: =IF(D37="PENDIENTE",C37,0) -> 0

Sheet PUSCHEL PABLO
A1: FECHA | B1: REPUESTO | C1: PRECIO | D1: CONDICION | E1: FACTURA | F1: VENDEDOR | H1: FACTURA | I1: DEUDA | J1: TOTAL DEUDA
A2: 44665 | B2: SALDO AJUSTE L200 | C2: 50000 | D2: PAGADO | F2: CESAR | H2: =IF(E:E="NO FACTURADO","PENDIENTE","AL DIA") -> AL DIA | I2: =IF(D2="PENDIENTE",C2,0) -> 0 | J2: =SUM(I:I) -> 0 | K2: MENU
I3: =IF(D3="PENDIENTE",C3,0) -> 0
I4: =IF(D4="PENDIENTE",C4,0) -> 0
I5: =IF(D5="PENDIENTE",C5,0) -> 0
I6: =IF(D6="PENDIENTE",C6,0) -> 0
I7: =IF(D7="PENDIENTE",C7,0) -> 0
I8: =IF(D8="PENDIENTE",C8,0) -> 0
I9: =IF(D9="PENDIENTE",C9,0) -> 0
I10: =IF(D10="PENDIENTE",C10,0) -> 0
I11: =IF(D11="PENDIENTE",C11,0) -> 0
I12: =IF(D12="PENDIENTE",C12,0) -> 0
I13: =IF(D13="PENDIENTE",C13,0) -> 0
I14: =IF(D14="PENDIENTE",C14,0) -> 0
... I37: =IF(D37="PENDIENTE",C37,0) -> 0

Sheet HENRIQUES JORGE (HUEVO)
A1: FECHA | B1: REPUESTO | C1: PRECIO | D1: CONDICION | E1: FACTURA | F1: VENDEDOR | H1: FACTURA | I1: DEUDA | J1: TOTAL DEUDA
A2: 44349 | B2: abono 50000 14/09 abono $10000 14/12/2022 | C2: 10000 | D2: pagado | H2: =IF(E:E="NO FACTURADO","PENDIENTE","AL DIA") -> AL DIA | I2: =IF(D2="PENDIENTE",C2,0) -> 0 | J2: =SUM(I:I) -> 12000 | K2: MENU
A3: 45524 | B3: amortiguador portalon h1 | C3: 13000 | D3: pagado | I3: =IF(D3="PENDIENTE",C3,0) -> 0
A4: 44430 | B4: saldo suspension h1 | C4: 12000 | D4: pendiente | I4: =IF(D4="PENDIENTE",C4,0) -> 12000 | L4: abono huevo 29/08/2024 $8000+8000 03/08
I5: =IF(D5="PENDIENTE",C5,0) -> 0
I6: =IF(D6="PENDIENTE",C6,0) -> 0
I7: =IF(D7="PENDIENTE",C7,0) -> 0
I8: =IF(D8="PENDIENTE",C8,0) -> 0
I9: =IF(D9="PENDIENTE",C9,0) -> 0
I10: =IF(D10="PENDIENTE",C10,0) -> 0
I11: =IF(D11="PENDIENTE",C11,0) -> 0
I12: =IF(D12="PENDIENTE",C12,0) -> 0
I13: =IF(D13="PENDIENTE",C13,0) -> 0
I14: =IF(D14="PENDIENTE",C14,0) -> 0
I15: =IF(D15="PENDIENTE",C15,0) -> 0
I16: =IF(D16="PENDIENTE",C16,0) -> 0
... I37: =IF(D37="PENDIENTE",C37,0) -> 0

Sheet ROA MANUEL
A1: FECHA | B1: REPUESTO | C1: PRECIO | D1: CONDICION | E1: FACTURA | F1: VENDEDOR | H1: FACTURA | I1: DEUDA | J1: TOTAL DEUDA
A2: 44358 | B2: CIL EMBR | C2: 67000 | D2: PENDIENTE | H2: =IF(E:E="NO FACTURADO","PENDIENTE","AL DIA") -> AL DIA | I2: =IF(D2="PENDIENTE",C2,0) -> 67000 | J2: =SUM(I:I) -> 356000 | K2: MENU
A3: 44359 | B3: ACEITE | C3: 24000 | D3: PENDIENTE | I3: =IF(D3="PENDIENTE",C3,0) -> 24000
B4: amortigua. Artiz | C4: 180000 | D4: PENDIENTE | I4: =IF(D4="PENDIENTE",C4,0) -> 180000
A5: 44373 | B5: RODAM | C5: 70000 | D5: PENDIENTE | I5: =IF(D5="PENDIENTE",C5,0) -> 70000
B6: pastillas | C6: 15000 | D6: PENDIENTE | I6: =IF(D6="PENDIENTE",C6,0) -> 15000
I7: =IF(D7="PENDIENTE",C7,0) -> 0
I8: =IF(D8="PENDIENTE",C8,0) -> 0
I9: =IF(D9="PENDIENTE",C9,0) -> 0
I10: =IF(D10="PENDIENTE",C10,0) -> 0
I11: =IF(D11="PENDIENTE",C11,0) -> 0
I12: =IF(D12="PENDIENTE",C12,0) -> 0
I13: =IF(D13="PENDIENTE",C13,0) -> 0
I14: =IF(D14="PENDIENTE",C14,0) -> 0
I15: =IF(D15="PENDIENTE",C15,0) -> 0
I16: =IF(D16="PENDIENTE",C16,0) -> 0
I17: =IF(D17="PENDIENTE",C17,0) -> 0
I18: =IF(D18="PENDIENTE",C18,0) -> 0
... I37: =IF(D37="PENDIENTE",C37,0) -> 0

Sheet BAHAMONDEZ JORGE
A1: FECHA | B1: REPUESTO | C1: PRECIO | D1: CONDICION | E1: FACTURA | F1: VENDEDOR | H1: FACTURA | I1: DEUDA | J1: TOTAL DEUDA
H2: =IF(E:E="NO FACTURADO","PENDIENTE","AL DIA") -> AL DIA | I2: =IF(D2="PENDIENTE",C2,0) -> 0 | J2: =SUM(I:I) -> 0 | K2: MENU
I3: =IF(D3="PENDIENTE",C3,0) -> 0
I4: =IF(D4="PENDIENTE",C4,0) -> 0
I5: =IF(D5="PENDIENTE",C5,0) -> 0
I6: =IF(D6="PENDIENTE",C6,0) -> 0
I7: =IF(D7="PENDIENTE",C7,0) -> 0
I8: =IF(D8="PENDIENTE",C8,0) -> 0
I9: =IF(D9="PENDIENTE",C9,0) -> 0
I10: =IF(D10="PENDIENTE",C10,0) -> 0
I11: =IF(D11="PENDIENTE",C11,0) -> 0
I12: =IF(D12="PENDIENTE",C12,0) -> 0
I13: =IF(D13="PENDIENTE",C13,0) -> 0
I14: =IF(D14="PENDIENTE",C14,0) -> 0
... I37: =IF(D37="PENDIENTE",C37,0) -> 0

Sheet VELASQUEZ MECANICO
A1: FECHA | B1: REPUESTO | C1: PRECIO | D1: CONDICION | E1: FACTURA | F1: VENDEDOR | H1: FACTURA | I1: DEUDA | J1: TOTAL DEUDA
H2: =IF(E:E="NO FACTURADO","PENDIENTE","AL DIA") -> AL DIA | I2: =IF(D2="PENDIENTE",C2,0) -> 0 | J2: =SUM(I:I) -> 0 | K2: MENU
I3: =IF(D3="PENDIENTE",C3,0) -> 0
I4: =IF(D4="PENDIENTE",C4,0) -> 0
I5: =IF(D5="PENDIENTE",C5,0) -> 0
I6: =IF(D6="PENDIENTE",C6,0) -> 0
I7: =IF(D7="PENDIENTE",C7,0) -> 0
I8: =IF(D8="PENDIENTE",C8,0) -> 0
I9: =IF(D9="PENDIENTE",C9,0) -> 0
I10: =IF(D10="PENDIENTE",C10,0) -> 0
I11: =IF(D11="PENDIENTE",C11,0) -> 0
I12: =IF(D12="PENDIENTE",C12,0) -> 0
I13: =IF(D13="PENDIENTE",C13,0) -> 0
I14: =IF(D14="PENDIENTE",C14,0) -> 0
... I37: =IF(D37="PENDIENTE",C37,0) -> 0

Sheet CONTRERAS SEBASTIAN (PAREJAJUST
A1: FECHA | B1: REPUESTO | C1: PRECIO | D1: CONDICION | E1: FACTURA | F1: VENDEDOR | H1: FACTURA | I1: DEUDA | J1: TOTAL DEUDA
A2: 44572 | B2: RODAMIENTO MAZA TERCEL | C2: 14000 | D2: pagado | E2: NO | F2: CESAR | H2: =IF(E:E="NO FACTURADO","PENDIENTE","AL DIA") -> AL DIA | I2: =IF(D2="PENDIENTE",C2,0) -> 0 | J2: =SUM(I:I) -> 38000 | K2: MENU
A3: 44596 | B3: accent 2005 hermana | C3: 14000 | D3: pagado | E3: no | F3: omar | I3: =IF(D3="PENDIENTE",C3,0) -> 0
A4: 44601 | B4: bateria 55 | C4: 40000 | D4: PAGADO | F4: delis | I4: =IF(D4="PENDIENTE",C4,0) -> 0
A5: 44606 | B5: PRESUPUESTO Nº4922 (LUV) | C5: 77500 | D5: pagado | E5: NO | F5: omar | I5: =IF(D5="PENDIENTE",C5,0) -> 0
A6: 44629 | B6: saldo pistola | C6: 40000 | D6: PAGADO | E6: NO | F6: delis | I6: =IF(D6="PENDIENTE",C6,0) -> 0
A7: 44677 | B7: metales towner | C7: 30000 | D7: PAGADO | E7: no | F7: omar | I7: =IF(D7="PENDIENTE",C7,0) -> 0
A8: 44704 | B8: CABLES BUJIAS ACCENT | C8: 15000 | D8: PAGADO | F8: CESAR | I8: =IF(D8="PENDIENTE",C8,0) -> 0
C9: 3000 | D9: PAGADO | I9: =IF(D9="PENDIENTE",C9,0) -> 0
A10: 44756 | B10: filtro aire y bujias baleno | C10: 15000 | D10: PAGADO | F10: omar | I10: =IF(D10="PENDIENTE",C10,0) -> 0
A11: 44776 | B11: Bandeja + rotula tercel 1998 | C11: 39000 | D11: PAGADO | F11: omar | I11: =IF(D11="PENDIENTE",C11,0) -> 0
A12: 44869 | B12: BATERIA 55AMPERES BEST Y CORREA TERCEL | C12: 63000 | D12: PAGADO | F12: omar | I12: =IF(D12="PENDIENTE",C12,0) -> 0
A13: 44875 | B13: poncho valvula baleno (16.000 ABONO 7.000) | C13: 7000 | D13: PAGADO | F13: omar | I13: =IF(D13="PENDIENTE",C13,0) -> 0 | L13: abono $20000 | M13: 45117
A14: 44893 | B14: aceite 10w40 + filtro | C14: 18000 | D14: pagado | F14: omar | I14: =IF(D14="PENDIENTE",C14,0) -> 0
A15: 44932 | B15: CORREA DMAX B39 | C15: 6000 | D15: pagado | F15: CESAR | I15: =IF(D15="PENDIENTE",C15,0) -> 0
A16: 44932 | B16: JUEGO BIELETAS DMAX BHORKE | C16: 30000 | D16: pagado | F16: CESAR | I16: =IF(D16="PENDIENTE",C16,0) -> 0
A17: 44938 | B17: JUEGO AMORTIGUADOR | C17: 38000 | D17: PENDIENTE | F17: CESAR | I17: =IF(D17="PENDIENTE",C17,0) -> 38000
I18: =IF(D18="PENDIENTE",C18,0) -> 0
I19: =IF(D19="PENDIENTE",C19,0) -> 0
I20: =IF(D20="PENDIENTE",C20,0) -> 0
I21: =IF(D21="PENDIENTE",C21,0) -> 0
I22: =IF(D22="PENDIENTE",C22,0) -> 0
I23: =IF(D23="PENDIENTE",C23,0) -> 0
I24: =IF(D24="PENDIENTE",C24,0) -> 0
I25: =IF(D25="PENDIENTE",C25,0) -> 0
I26: =IF(D26="PENDIENTE",C26,0) -> 0
I27: =IF(D27="PENDIENTE",C27,0) -> 0
I28: =IF(D28="PENDIENTE",C28,0) -> 0
I29: =IF(D29="PENDIENTE",C29,0) -> 0
... I37: =IF(D37="PENDIENTE",C37,0) -> 0

Sheet CARRASCO PEDRO (ZORRO)
A1: FECHA | B1: REPUESTO | C1: PRECIO | D1: CONDICION | E1: FACTURA | F1: VENDEDOR | H1: FACTURA | I1: DEUDA | J1: TOTAL DEUDA
A2: 44408 | C2: 14000 | D2: pagado | H2: =IF(E:E="NO FACTURADO","PENDIENTE","AL DIA") -> AL DIA | I2: =IF(D2="PENDIENTE",C2,0) -> 0 | J2: =SUM(I:I) -> 28000 | K2: MENU
A3: 44620 | B3: AROMATIZANTE PASTILLA | C3: 15000 | D3: pagado | I3: =IF(D3="PENDIENTE",C3,0) -> 0
A4: 44830 | B4: shampo con cera | C4: 9000 | D4: pagado | F4: cesar | I4: =IF(D4="PENDIENTE",C4,0) -> 0
A5: 45042 | B5: SALDO 5W/30 | C5: 30000 | D5: pagado | F5: DELIS | I5: =IF(D5="PENDIENTE",C5,0) -> 0
A6: 45086 | B6: disco freno | C6: 40000 | D6: pagado | F6: DELIS | I6: =IF(D6="PENDIENTE",C6,0) -> 0
A7: 45267 | B7: KIT DISTRIBUCION BBA AGUA SALDO | C7: 50000 | D7: pagado | F7: CESAR | I7: =IF(D7="PENDIENTE",C7,0) -> 0
A8: 45526 | B8: SALDO 5W/30 | C8: 28000 | D8: pendiente | F8: cesar | I8: =IF(D8="PENDIENTE",C8,0) -> 28000
I9: =IF(D9="PENDIENTE",C9,0) -> 0
I10: =IF(D10="PENDIENTE",C10,0) -> 0
I11: =IF(D11="PENDIENTE",C11,0) -> 0
I12: =IF(D12="PENDIENTE",C12,0) -> 0
I13: =IF(D13="PENDIENTE",C13,0) -> 0
I14: =IF(D14="PENDIENTE",C14,0) -> 0
I15: =IF(D15="PENDIENTE",C15,0) -> 0
I16: =IF(D16="PENDIENTE",C16,0) -> 0
I17: =IF(D17="PENDIENTE",C17,0) -> 0
I18: =IF(D18="PENDIENTE",C18,0) -> 0
I19: =IF(D19="PENDIENTE",C19,0) -> 0
I20: =IF(D20="PENDIENTE",C20,0) -> 0
... I37: =IF(D37="PENDIENTE",C37,0) -> 0

Sheet TIO CHINO LESPAI
A1: FECHA | B1: REPUESTO | C1: PRECIO | D1: CONDICION | E1: FACTURA | F1: VENDEDOR | H1: FACTURA | I1: DEUDA | J1: TOTAL DEUDA
A2: 44578 | B2: PARACHOQUE DELANTERO LUV | C2: 0 | D2: PENDIENTE | E2: NOP | F2: DELIS | H2: =IF(E:E="NO FACTURADO","PENDIENTE","AL DIA") -> AL DIA | I2: =IF(D2="PENDIENTE",C2,0) -> 0 | J2: 0 | K2: MENU | L2: abono 20000 | M2: 44634
A3: 44657 | B3: BATERIA SALDO | C3: 15000 | D3: pagado | E3: NOP | F3: DELIS | I3: =IF(D3="PENDIENTE",C3,0) -> 0
A4: 45033 | B4: SALDO FOCO | C4: 6000 | D4: pagado | F4: DELIS | I4: =IF(D4="PENDIENTE",C4,0) -> 0
A5: 45090 | B5: BOMBA CEBADORA | C5: 25000 | D5: pagado | I5: =IF(D5="PENDIENTE",C5,0) -> 0
A6: 45090 | B6: JGO BUJIAS | C6: 24000 | D6: pagado | I6: =IF(D6="PENDIENTE",C6,0) -> 0 | L6: ABONO $60000 | M6: 45091
A7: 45090 | B7: CILINDRO FRENO | C7: 25000 | D7: pagado | I7: =IF(D7="PENDIENTE",C7,0) -> 0
A8: 45090 | B8: LIQUIDO FRENO | C8: 4500 | D8: pagado | I8: =IF(D8="PENDIENTE",C8,0) -> 0
A9: 45090 | B9: MANILLA PUERTA RH | C9: 5000 | D9: pagado | I9: =IF(D9="PENDIENTE",C9,0) -> 0
A10: 45252 | B10: RODAMIENTO Y HORQUILLA EMBRAGUE YD25 MACACO | C10: 35000 | D10: pagado | I10: =IF(D10="PENDIENTE",C10,0) -> 0
I11: =IF(D11="PENDIENTE",C11,0) -> 0
I12: =IF(D12="PENDIENTE",C12,0) -> 0
I13: =IF(D13="PENDIENTE",C13,0) -> 0
I14: =IF(D14="PENDIENTE",C14,0) -> 0
I15: =IF(D15="PENDIENTE",C15,0) -> 0
I16: =IF(D16="PENDIENTE",C16,0) -> 0
I17: =IF(D17="PENDIENTE",C17,0) -> 0
I18: =IF(D18="PENDIENTE",C18,0) -> 0
I19: =IF(D19="PENDIENTE",C19,0) -> 0
I20: =IF(D20="PENDIENTE",C20,0) -> 0
I21: =IF(D21="PENDIENTE",C21,0) -> 0
I22: =IF(D22="PENDIENTE",C22,0) -> 0
... I37: =IF(D37="PENDIENTE",C37,0) -> 0

Sheet BAHAMONDEZ MARCO (SUBOFICIAL)
A1: FECHA | B1: REPUESTO | C1: PRECIO | D1: CONDICION | E1: FACTURA | F1: VENDEDOR | H1: FACTURA | I1: DEUDA | J1: TOTAL DEUDA
A2: 44558 | B2: ACEITE BUJIAS EMP. | C2: 43000 | D2: PAGADO | H2: =IF(E:E="NO FACTURADO","PENDIENTE","AL DIA") -> AL DIA | I2: =IF(D2="PENDIENTE",C2,0) -> 0 | J2: =SUM(I:I) -> 201500 | K2: MENU
A3: 44558 | B3: cable bujia roedores sensor T limpiainyectores | C3: 20900 | D3: PAGADO | I3: =IF(D3="PENDIENTE",C3,0) -> 0
A4: 44558 | B4: hijo | C4: 115000 | D4: PAGADO | I4: =IF(D4="PENDIENTE",C4,0) -> 0
A5: 44589 | B5: BATERIA 55 AMP ROCKET | C5: 60000 | D5: PAGADO | E5: NO | F5: OMAR | I5: =IF(D5="PENDIENTE",C5,0) -> 0
A6: 44656 | B6: PRESUPUESTO Nº5104 | C6: 30800 | D6: PAGADO | I6: =IF(D6="PENDIENTE",C6,0) -> 0
A7: 44663 | B7: REPUESTOS SAIL BIELETA CAZOLETA TERMINALES | C7: 7800 | D7: PAGADO | I7: =IF(D7="PENDIENTE",C7,0) -> 0
A8: 44818 | B8: gotita afinamiento luv 2,2 shell | C8: 19000 | D8: PAGADO | F8: delis | I8: =IF(D8="PENDIENTE",C8,0) -> 0 | K8: ABONO $50000 22/02/2023
A9: 44818 | B9: pino aromatico | C9: 1000 | D9: PAGADO | F9: delis | I9: =IF(D9="PENDIENTE",C9,0) -> 0
A10: 44851 | B10: kit embrague sail | C10: 40000 | D10: PAGADO | F10: cesar | I10: =IF(D10="PENDIENTE",C10,0) -> 0 | K10: ABONO $50000 06/06/2023
A11: 44872 | B11: BATERIA CUÑADO | C11: 50000 | D11: pagado | F11: delis | I11: =IF(D11="PENDIENTE",C11,0) -> 0 | K11: abono 50000 22/02/2023
A12: 45096 | B12: BULBO FRENO SAIL | C12: 7500 | D12: pagado | F12: delis | I12: =IF(D12="PENDIENTE",C12,0) -> 0
A13: 45237 | B13: BANDEJA 2RODAMIENTO | C13: 13000 | D13: pagado | F13: delis | I13: =IF(D13="PENDIENTE",C13,0) -> 0 | K13: abono $34000 21/12/2023
A14: 45260 | B14: FLOTADOR LUV | C14: 25000 | D14: PAGADO | F14: delis | I14: =IF(D14="PENDIENTE",C14,0) -> 0
A15: 45261 | B15: BATERIA 90 AMP | C15: 70000 | D15: pendiente | E15: $50.000 | I15: =IF(D15="PENDIENTE",C15,0) -> 70000
A16: 44934 | B16: AMORTIGUADORES QUASQUAI | C16: 50000 | D16: pendiente | E16: $100,000 | I16: =IF(D16="PENDIENTE",C16,0) -> 50000 | K16: ABONO 50000 19/04/2024
A17: 44934 | B17: BIELETA QUASQUAI | C17: 4500 | D17: pendiente | I17: =IF(D17="PENDIENTE",C17,0) -> 4500
A18: 44934 | B18: CAZOLETA QUASQUAI | C18: 6000 | D18: PAGADO | E18: $56,000 | I18: =IF(D18="PENDIENTE",C18,0) -> 0 | K18: abono $50,000 09/04/2024
B19: TERMINAL DIRECCION | C19: 44000 | D19: pendiente | I19: =IF(D19="PENDIENTE",C19,0) -> 44000 | K19: abono $50000 26/06/2024
A20: 45481 | B20: afinamiento sail | C20: 33000 | D20: pendiente | I20: =IF(D20="PENDIENTE",C20,0) -> 33000 | K20: ABONO $50000 2/10/2024
I21: =IF(D21="PENDIENTE",C21,0) -> 0
I22: =IF(D22="PENDIENTE",C22,0) -> 0
I23: =IF(D23="PENDIENTE",C23,0) -> 0
I24: =IF(D24="PENDIENTE",C24,0) -> 0
I25: =IF(D25="PENDIENTE",C25,0) -> 0
I26: =IF(D26="PENDIENTE",C26,0) -> 0
I27: =IF(D27="PENDIENTE",C27,0) -> 0
I28: =IF(D28="PENDIENTE",C28,0) -> 0
I29: =IF(D29="PENDIENTE",C29,0) -> 0
I30: =IF(D30="PENDIENTE",C30,0) -> 0
I31: =IF(D31="PENDIENTE",C31,0) -> 0
I32: =IF(D32="PENDIENTE",C32,0) -> 0
... I36: =IF(D36="PENDIENTE",C36,0) -> 0

Sheet PINUER OMAR
A1: FECHA | B1: REPUESTO | C1: PRECIO | D1: CONDICION | E1: FACTURA | F1: VENDEDOR | H1: FACTURA | I1: DEUDA | J1: TOTAL DEUDA
A2: 44617 | B2: galon aceite 15w40 | C2: 20000 | D2: pendiente | E2: no | F2: omar | H2: =IF(E:E="NO FACTURADO","PENDIENTE","AL DIA") -> AL DIA | I2: =IF(D2="PENDIENTE",C2,0) -> 20000 | J2: =SUM(I:I) -> 126000 | K2: MENU
B3: AFINAMIENTO JGO EMP | C3: 94000 | D3: pendiente | F3: CESAR | I3: =IF(D3="PENDIENTE",C3,0) -> 94000
A4: 44641 | B4: FILTRO AIRE | C4: 12000 | D4: pendiente | F4: CESAR | I4: =IF(D4="PENDIENTE",C4,0) -> 12000
I5: =IF(D5="PENDIENTE",C5,0) -> 0
I6: =IF(D6="PENDIENTE",C6,0) -> 0
I7: =IF(D7="PENDIENTE",C7,0) -> 0
I8: =IF(D8="PENDIENTE",C8,0) -> 0
I9: =IF(D9="PENDIENTE",C9,0) -> 0
I10: =IF(D10="PENDIENTE",C10,0) -> 0
I11: =IF(D11="PENDIENTE",C11,0) -> 0
I12: =IF(D12="PENDIENTE",C12,0) -> 0
I13: =IF(D13="PENDIENTE",C13,0) -> 0
I14: =IF(D14="PENDIENTE",C14,0) -> 0
I15: =IF(D15="PENDIENTE",C15,0) -> 0
I16: =IF(D16="PENDIENTE",C16,0) -> 0
... I37: =IF(D37="PENDIENTE",C37,0) -> 0

Sheet HERNANDEZ HECTOR (FALABELLA)
A1: FECHA | B1: REPUESTO | C1: PRECIO | D1: CONDICION | E1: FACTURA | F1: VENDEDOR | H1: FACTURA | I1: DEUDA | J1: TOTAL DEUDA
H2: =IF(E:E="NO FACTURADO","PENDIENTE","AL DIA") -> AL DIA | I2: =IF(D2="PENDIENTE",C2,0) -> 0 | J2: =SUM(I:I) -> 0 | K2: MENU
I3: =IF(D3="PENDIENTE",C3,0) -> 0
I4: =IF(D4="PENDIENTE",C4,0) -> 0
I5: =IF(D5="PENDIENTE",C5,0) -> 0
I6: =IF(D6="PENDIENTE",C6,0) -> 0
I7: =IF(D7="PENDIENTE",C7,0) -> 0
I8: =IF(D8="PENDIENTE",C8,0) -> 0
I9: =IF(D9="PENDIENTE",C9,0) -> 0
I10: =IF(D10="PENDIENTE",C10,0) -> 0
I11: =IF(D11="PENDIENTE",C11,0) -> 0
I12: =IF(D12="PENDIENTE",C12,0) -> 0
I13: =IF(D13="PENDIENTE",C13,0) -> 0
I14: =IF(D14="PENDIENTE",C14,0) -> 0
... I37: =IF(D37="PENDIENTE",C37,0) -> 0

Sheet BARRIA MIGUEL
A1: FECHA | B1: REPUESTO | C1: PRECIO | D1: CONDICION | E1: FACTURA | F1: VENDEDOR | H1: FACTURA | I1: DEUDA | J1: TOTAL DEUDA
A2: 44575 | B2: BOBINA | C2: 18500 | D2: pagado | F2: DELIS | H2: =IF(E:E="NO FACTURADO","PENDIENTE","AL DIA") -> AL DIA | I2: =IF(D2="PENDIENTE",C2,0) -> 0 | J2: =SUM(I:I) -> 3000 | K2: MENU
A3: 44581 | B3: BOMBA BENCINA CARRY | C3: 18000 | D3: pagado | F3: DELIS | I3: =IF(D3="PENDIENTE",C3,0) -> 0
A4: 44589 | B4: JGO ROTULAS DMAX | C4: 70000 | D4: pagado | F4: CESAR | I4: =IF(D4="PENDIENTE",C4,0) -> 0
A5: 44599 | B5: JGO AMORTIGUADORES DELANTEROS | C5: 40000 | D5: pagado | F5: DELIS | I5: =IF(D5="PENDIENTE",C5,0) -> 0
A6: 11 02 2022 | B6: amortiguadores | C6: 130000 | D6: pagado | F6: delis | I6: =IF(D6="PENDIENTE",C6,0) -> 0
A7: 44861 | B7: saldo disco y pastilla | C7: 3000 | D7: pendiente | F7: DELIS | I7: =IF(D7="PENDIENTE",C7,0) -> 3000
I8: =IF(D8="PENDIENTE",C8,0) -> 0
I9: =IF(D9="PENDIENTE",C9,0) -> 0
I10: =IF(D10="PENDIENTE",C10,0) -> 0
I11: =IF(D11="PENDIENTE",C11,0) -> 0
I12: =IF(D12="PENDIENTE",C12,0) -> 0
I13: =IF(D13="PENDIENTE",C13,0) -> 0
I14: =IF(D14="PENDIENTE",C14,0) -> 0
I15: =IF(D15="PENDIENTE",C15,0) -> 0
I16: =IF(D16="PENDIENTE",C16,0) -> 0
I17: =IF(D17="PENDIENTE",C17,0) -> 0
I18: =IF(D18="PENDIENTE",C18,0) -> 0
I19: =IF(D19="PENDIENTE",C19,0) -> 0
... I37: =IF(D37="PENDIENTE",C37,0) -> 0

Sheet ROBLES LUIS
A1: FECHA | B1: REPUESTO | C1: PRECIO | D1: CONDICION | E1: FACTURA | F1: VENDEDOR | H1: FACTURA | I1: DEUDA | J1: TOTAL DEUDA
A2: 44536 | B2: SALDO BOMBA DIRECCION | C2: 0 | D2: COBRADO | E2: NO | H2: =IF(E:E="NO FACTURADO","PENDIENTE","AL DIA") -> AL DIA | I2: =IF(D2="PENDIENTE",C2,0) -> 0 | J2: =SUM(I:I) -> 0 | K2: MENU
A3: 44676 | B3: A FAVOR | C3: 61000 | I3: =IF(D3="PENDIENTE",C3,0) -> 0
B4: a favor | C4: 41000 | I4: =IF(D4="PENDIENTE",C4,0) -> 0
B5: a favor | C5: 23000 | E5: no | I5: =IF(D5="PENDIENTE",C5,0) -> 0 | K5: 44859
I6: =IF(D6="PENDIENTE",C6,0) -> 0
I7: =IF(D7="PENDIENTE",C7,0) -> 0
I8: =IF(D8="PENDIENTE",C8,0) -> 0
I9: =IF(D9="PENDIENTE",C9,0) -> 0
I10: =IF(D10="PENDIENTE",C10,0) -> 0
I11: =IF(D11="PENDIENTE",C11,0) -> 0
I12: =IF(D12="PENDIENTE",C12,0) -> 0
I13: =IF(D13="PENDIENTE",C13,0) -> 0
I14: =IF(D14="PENDIENTE",C14,0) -> 0
I15: =IF(D15="PENDIENTE",C15,0) -> 0
I16: =IF(D16="PENDIENTE",C16,0) -> 0
I17: =IF(D17="PENDIENTE",C17,0) -> 0
... I37: =IF(D37="PENDIENTE",C37,0) -> 0

Sheet SOBARZO RODOLFO
A1: FECHA | B1: REPUESTO | C1: PRECIO | D1: CONDICION | E1: FACTURA | F1: VENDEDOR | H1: FACTURA | I1: DEUDA | J1: TOTAL DEUDA
A2: 44572 | B2: kit distribucion | C2: 17000 | D2: pagado | H2: =IF(E:E="NO FACTURADO","PENDIENTE","AL DIA") -> AL DIA | I2: =IF(D2="PENDIENTE",C2,0) -> 0 | J2: =SUM(I:I) -> 0 | K2: MENU
A3: 44614 | B3: JGO AXIALES | C3: 32000 | D3: pagado | E3: NO | F3: CESAR | I3: =IF(D3="PENDIENTE",C3,0) -> 0
A4: 44705 | B4: jgo bujia | C4: 20000 | D4: pagado | F4: cesar | I4: =IF(D4="PENDIENTE",C4,0) -> 0
A5: 44734 | B5: bateria 90 amperes | C5: 30000 | D5: pagado | F5: delis | I5: =IF(D5="PENDIENTE",C5,0) -> 0
A6: 44805 | B6: SALDO FOCO TRASERO HILUX | C6: 25000 | D6: pagado | F6: CESAR | I6: =IF(D6="PENDIENTE",C6,0) -> 0
A7: 44900 | B7: bujias incandescente (2) | C7: 14000 | D7: pagado | I7: =IF(D7="PENDIENTE",C7,0) -> 0
A8: 44914 | B8: saldo rotula | C8: 25000 | D8: pagado | F8: delis | I8: =IF(D8="PENDIENTE",C8,0) -> 0
A9: 44914 | B9: jugo patines | C9: 1500 | D9: pagado | I9: =IF(D9="PENDIENTE",C9,0) -> 0
A10: 45048 | B10: JGO BUJIAS | C10: 28000 | D10: pagado | F10: CESAR | I10: =IF(D10="PENDIENTE",C10,0) -> 0
A11: 45168 | B11: saldo kit distribucion | C11: 40000 | D11: pagado | I11: =IF(D11="PENDIENTE",C11,0) -> 0
A12: 45253 | B12: disco freno empaquetadura media | C12: 55000 | D12: pagado | F12: delis | I12: =IF(D12="PENDIENTE",C12,0) -> 0 | L12: abono $30000 01/12/2023 $25000 19/12/2023
A13: 45352 | B13: filtro aire h1 | C13: 10000 | D13: pagado | I13: =IF(D13="PENDIENTE",C13,0) -> 0
I14: =IF(D14="PENDIENTE",C14,0) -> 0
I15: =IF(D15="PENDIENTE",C15,0) -> 0
I16: =IF(D16="PENDIENTE",C16,0) -> 0
I17: =IF(D17="PENDIENTE",C17,0) -> 0
I18: =IF(D18="PENDIENTE",C18,0) -> 0
I19: =IF(D19="PENDIENTE",C19,0) -> 0
I20: =IF(D20="PENDIENTE",C20,0) -> 0
I21: =IF(D21="PENDIENTE",C21,0) -> 0
I22: =IF(D22="PENDIENTE",C22,0) -> 0
I23: =IF(D23="PENDIENTE",C23,0) -> 0
I24: =IF(D24="PENDIENTE",C24,0) -> 0
I25: =IF(D25="PENDIENTE",C25,0) -> 0
... I37: =IF(D37="PENDIENTE",C37,0) -> 0

Sheet AGUILAR HANZ
A1: FECHA | B1: REPUESTO | C1: PRECIO | D1: CONDICION | E1: FACTURA | F1: VENDEDOR | H1: FACTURA | I1: DEUDA | J1: TOTAL DEUDA
A2: 44552 | B2: SALDO V16 | C2: 0 | D2: PENDIENTE | E2: NO | H2: =IF(E:E="NO FACTURADO","PENDIENTE","AL DIA") -> AL DIA | I2: =IF(D2="PENDIENTE",C2,0) -> 0 | J2: =SUM(I:I) -> 189000 | K2: MENU
A3: 44860 | B3: saldo factura nº6898 | C3: 81000 | D3: PAGADO | I3: =IF(D3="PENDIENTE",C3,0) -> 0
A4: 44908 | B4: mazasa traseras | C4: 50000 | D4: PAGADO | F4: cesar | I4: =IF(D4="PENDIENTE",C4,0) -> 0
A5: 45027 | B5: PRESUPUESTO 5708 SALDO ABONO 100000 | C5: 170000 | D5: PENDIENTE | F5: cesar | I5: =IF(D5="PENDIENTE",C5,0) -> 170000 | L5: ABONO $100.000 14/05/2023
A6: 45051 | B6: PRESUPUESTO 5727 | C6: 19000 | D6: PENDIENTE | F6: cesar | I6: =IF(D6="PENDIENTE",C6,0) -> 19000 | L6: abono $30000 | M6: 45202
I7: =IF(D7="PENDIENTE",C7,0) -> 0
I8: =IF(D8="PENDIENTE",C8,0) -> 0
I9: =IF(D9="PENDIENTE",C9,0) -> 0
I10: =IF(D10="PENDIENTE",C10,0) -> 0
I11: =IF(D11="PENDIENTE",C11,0) -> 0
I12: =IF(D12="PENDIENTE",C12,0) -> 0
I13: =IF(D13="PENDIENTE",C13,0) -> 0
I14: =IF(D14="PENDIENTE",C14,0) -> 0
I15: =IF(D15="PENDIENTE",C15,0) -> 0
I16: =IF(D16="PENDIENTE",C16,0) -> 0
I17: =IF(D17="PENDIENTE",C17,0) -> 0
I18: =IF(D18="PENDIENTE",C18,0) -> 0
... I37: =IF(D37="PENDIENTE",C37,0) -> 0

Sheet VENEGAS EFRAIN BERNABE
A1: FECHA | B1: REPUESTO | C1: PRECIO | D1: CONDICION | E1: FACTURA | F1: VENDEDOR | H1: FACTURA | I1: DEUDA | J1: TOTAL DEUDA
B2: SALDO FILTRO MONTERO | C2: 9000 | D2: PAGADO | E2: NO | H2: =IF(E:E="NO FACTURADO","PENDIENTE","AL DIA") -> AL DIA | I2: =IF(D2="PENDIENTE",C2,0) -> 0 | J2: =SUM(I:I) -> 0 | K2: MENU
A3: 45644 | B3: rodamiento sacaperno | C3: 28000 | D3: PAGADO | I3: =IF(D3="PENDIENTE",C3,0) -> 0
I4: =IF(D4="PENDIENTE",C4,0) -> 0
I5: =IF(D5="PENDIENTE",C5,0) -> 0
I6: =IF(D6="PENDIENTE",C6,0) -> 0
I7: =IF(D7="PENDIENTE",C7,0) -> 0
I8: =IF(D8="PENDIENTE",C8,0) -> 0
I9: =IF(D9="PENDIENTE",C9,0) -> 0
I10: =IF(D10="PENDIENTE",C10,0) -> 0
I11: =IF(D11="PENDIENTE",C11,0) -> 0
I12: =IF(D12="PENDIENTE",C12,0) -> 0
I13: =IF(D13="PENDIENTE",C13,0) -> 0
I14: =IF(D14="PENDIENTE",C14,0) -> 0
I15: =IF(D15="PENDIENTE",C15,0) -> 0
... I37: =IF(D37="PENDIENTE",C37,0) -> 0

Sheet MONTES WALTER (LOCO EDY)
A1: FECHA | B1: REPUESTO | C1: PRECIO | D1: CONDICION | E1: FACTURA | F1: VENDEDOR | H1: FACTURA | I1: DEUDA | J1: TOTAL DEUDA
